Workbook
Name Accelera_Clear_SATIN_additional_topcoat: Epoxy!$T$170
Name Accelera_ClearEXT: Epoxy!$T$168
Name Accelera_PgmntEXT: Epoxy!$T$169
Name AT_Clear_Satin_w_Grit: Epoxy!$T$158
Name AT_ClearGloss_wGrit: Epoxy!$T$159
Name AT_ClearSatin_wGrit: Epoxy!$O$24
Name AT_Pgmt_Gloss_w_Grit: Epoxy!$T$161
Name AT_Pgmt_Satin_w_Grit: Epoxy!$T$160
Name ColorFast: Epoxy!$T$164
Name CoveRez: Epoxy!$T$152
Name Elast_O_Coat_Clear: Epoxy!$T$147
Name Fiberglass_Mat: Epoxy!$W$151
Name Gard_No_Sag: Epoxy!$T$150
Name GardReg: Epoxy!$T$149
Name Glaze4: Epoxy!$T$153
Name HP_Block_Filler_Primer: Epoxy!$T$174
Name HP_Eggshell_Topcoat: Epoxy!$T$175
Name HP_Gripper_Primer: Epoxy!$T$173
Name HP_Satin_Topcoat: Epoxy!$T$176
Name MACROFlake: Epoxy!$W$146
Name MD: Epoxy!$T$163
Name microFlake: Epoxy!$W$147
Name MVP: Epoxy!$T$146
Name NovolacGard: Epoxy!$T$155
Name OPF: Epoxy!$T$151
Name Q11_25a: Epoxy!$W$149
Name Q28_40s: Epoxy!$W$148
Name ShopFloor: Epoxy!$T$154
Name Silica: Epoxy!$W$145
Name SL: Epoxy!$T$162
Name TF_Reg: Epoxy!$T$165
Name WB: Epoxy!$T$145
Name WR: Epoxy!$T$167
Name ZincCoveCap: Epoxy!$W$150

Sheet Epoxy
A1: Project | G1: Bidding Contacts: | L1: MVP $ / SF Ranges: (08/2023)
A2: Bid Date | L2: 3 | M2: Standard
A3: Address | L3: 3.25 | M3: < 1,500 sf * | N3: * use your
A4: Local? | B4: Yes | C4: < 70 miles? | L4: 2.75 | M4: > 10,000 sf * | N4: discretion | AK4: 1000 | AN4: =AK4 | AQ4: =AK4+AN4 | AT4: =AQ4 | AU4: =IF(AK4<=#REF!,#REF!,IF(AK4<=#REF!,#REF!,IF(AK4<=#REF!,#REF!,IF(AK4<=#REF!,#REF!,IF(AK4<=#REF!,#REF!,IF(AK4<=#REF!,#REF!,IF(AK4<=#REF!,#REF!,0.05))))))) | AV4: =AU4*AK4 | AX4: =IF(AN4<=#REF!,#REF!,IF(AN4<=#REF!,#REF!,IF(AN4<=#REF!,#REF!,IF(AN4<=#REF!,#REF!,IF(AN4<=#REF!,#REF!,IF(AN4<=#REF!,#REF!,IF(AN4<=#REF!,#REF!,0.05))))))) | AY4: =AX4*AN4 | BA4: =IF(AQ4<=#REF!,#REF!,IF(AQ4<=#REF!,#REF!,IF(AQ4<=#REF!,#REF!,IF(AQ4<=#REF!,#REF!,IF(AQ4<=#REF!,#REF!,IF(AQ4<=#REF!,#REF!,IF(AQ4<=#REF!,#REF!,0.05))))))) | BB4: =BA4*SUM(AY4,AV4,AQ4) | BD4: =IF(AT4<=#REF!,#REF!,IF(AT4<=#REF!,#REF!,IF(AT4<=#REF!,#REF!,IF(AT4<=#REF!,#REF!,IF(AT4<=#REF!,#REF!,IF(AT4<=#REF!,#REF!,IF(AT4<=#REF!,#REF!,0.05))))))) | BE4: =BD4*AT4 | BG4: =0.07*SUM(AQ4,AV4,AY4,BB4,BE4) | BI4: =SUM(BG4,BE4,BB4,AY4,AV4,AQ4) | BJ4: =SUM(BE4,BB4,AY4,AV4) | BK4: =BJ4/BI4 | BN4: 0.1 | BO4: 5000 | BQ4: 0.35 | BR4: 2000 | BT4: 0.28 | BU4: 9000 | BW4: 0 | BX4: 9000 | CA4: 1000 | CD4: =CA4 | CG4: =CA4+CD4 | CJ4: =CG4 | CK4: =IF(CA4<=BO$4,BN$4,IF(CA4<=BO$5,BN$5,IF(CA4<=BO$6,BN$6,IF(CA4<=BO$7,BN$7,IF(CA4<=BO$12,BN$12,IF(CA4<=BO$13,BN$13,IF(CA4<=BO$14,BN$14,0.05))))))) | CL4: =CK4*CA4 | CN4: =IF(CD4<=BR$4,BQ$4,IF(CD4<=BR$5,BQ$5,IF(CD4<=BR$6,BQ$6,IF(CD4<=BR$7,BQ$7,IF(CD4<=BR$12,BQ$12,IF(CD4<=BR$13,BQ$13,IF(CD4<=BR$14,BQ$14,0.05))))))) | CO4: =CN4*CD4 | CQ4: =IF(CG4<=BU$4,BT$4,IF(CG4<=BU$5,BT$5,IF(CG4<=BU$6,BT$6,IF(CG4<=BU$7,BT$7,IF(CG4<=BU$12,BT$12,IF(CG4<=BU$13,BT$13,IF(CG4<=BU$14,BT$14,0.05))))))) | CR4: =CQ4*SUM(CO4,CL4,CG4) | CT4: =IF(CJ4<=BX$4,BW$4,IF(CJ4<=BX$5,BW$5,IF(CJ4<=BX$6,BW$6,IF(CJ4<=BX$7,BW$7,IF(CJ4<=BX$12,BW$12,IF(CJ4<=BX$13,BW$13,IF(CJ4<=BX$14,BW$14,0.05))))))) | CU4: =CT4*CJ4 | CW4: =0.07*SUM(CG4,CL4,CO4,CR4,CU4) | CY4: =SUM(CW4,CU4,CR4,CO4,CL4,CG4) | CZ4: =SUM(CU4,CR4,CO4,CL4) | DA4: =CZ4/CY4
A5: Hard Bid? | B5: No | C5: PrevailingWage? | D5: No | AK5: 2000 | AN5: =AK5 | AQ5: =AK5+AN5 | AT5: =AQ5 | AU5: =IF(AK5<=#REF!,#REF!,IF(AK5<=#REF!,#REF!,IF(AK5<=#REF!,#REF!,IF(AK5<=#REF!,#REF!,IF(AK5<=#REF!,#REF!,IF(AK5<=#REF!,#REF!,IF(AK5<=#REF!,#REF!,0.05))))))) | AV5: =AU5*AK5 | AX5: =IF(AN5<=#REF!,#REF!,IF(AN5<=#REF!,#REF!,IF(AN5<=#REF!,#REF!,IF(AN5<=#REF!,#REF!,IF(AN5<=#REF!,#REF!,IF(AN5<=#REF!,#REF!,IF(AN5<=#REF!,#REF!,0.05))))))) | AY5: =AX5*AN5 | BA5: =IF(AQ5<=#REF!,#REF!,IF(AQ5<=#REF!,#REF!,IF(AQ5<=#REF!,#REF!,IF(AQ5<=#REF!,#REF!,IF(AQ5<=#REF!,#REF!,IF(AQ5<=#REF!,#REF!,IF(AQ5<=#REF!,#REF!,0.05))))))) | BB5: =BA5*SUM(AY5,AV5,AQ5) | BD5: =IF(AT5<=#REF!,#REF!,IF(AT5<=#REF!,#REF!,IF(AT5<=#REF!,#REF!,IF(AT5<=#REF!,#REF!,IF(AT5<=#REF!,#REF!,IF(AT5<=#REF!,#REF!,IF(AT5<=#REF!,#REF!,0.05))))))) | BE5: =BD5*AT5 | BG5: =0.07*SUM(AQ5,AV5,AY5,BB5,BE5) | BI5: =SUM(BG5,BE5,BB5,AY5,AV5,AQ5) | BJ5: =SUM(BE5,BB5,AY5,AV5) | BK5: =BJ5/BI5 | BN5: 0.05 | BO5: 1000000000 | BQ5: 0.3 | BR5: 3000 | BT5: 0.24 | BU5: 14000 | BW5: -0.04 | BX5: 14000 | CA5: 2000 | CD5: =CA5 | CG5: =CA5+CD5 | CJ5: =CG5 | CK5: =IF(CA5<=BO$4,BN$4,IF(CA5<=BO$5,BN$5,IF(CA5<=BO$6,BN$6,IF(CA5<=BO$7,BN$7,IF(CA5<=BO$12,BN$12,IF(CA5<=BO$13,BN$13,IF(CA5<=BO$14,BN$14,0.05))))))) | CL5: =CK5*CA5 | CN5: =IF(CD5<=BR$4,BQ$4,IF(CD5<=BR$5,BQ$5,IF(CD5<=BR$6,BQ$6,IF(CD5<=BR$7,BQ$7,IF(CD5<=BR$12,BQ$12,IF(CD5<=BR$13,BQ$13,IF(CD5<=BR$14,BQ$14,0.05))))))) | CO5: =CN5*CD5 | CQ5: =IF(CG5<=BU$4,BT$4,IF(CG5<=BU$5,BT$5,IF(CG5<=BU$6,BT$6,IF(CG5<=BU$7,BT$7,IF(CG5<=BU$12,BT$12,IF(CG5<=BU$13,BT$13,IF(CG5<=BU$14,BT$14,0.05))))))) | CR5: =CQ5*SUM(CO5,CL5,CG5) | CT5: =IF(CJ5<=BX$4,BW$4,IF(CJ5<=BX$5,BW$5,IF(CJ5<=BX$6,BW$6,IF(CJ5<=BX$7,BW$7,IF(CJ5<=BX$12,BW$12,IF(CJ5<=BX$13,BW$13,IF(CJ5<=BX$14,BW$14,0.05))))))) | CU5: =CT5*CJ5 | CW5: =0.07*SUM(CG5,CL5,CO5,CR5,CU5) | CY5: =SUM(CW5,CU5,CR5,CO5,CL5,CG5) | CZ5: =SUM(CU5,CR5,CO5,CL5) | DA5: =CZ5/CY5
A6: Taxable? | B6: Yes | C6: Remodel Tax? | D6: No | AK6: 3000 | AN6: =AK6 | AQ6: =AK6+AN6 | AT6: =AQ6 | AU6: =IF(AK6<=#REF!,#REF!,IF(AK6<=#REF!,#REF!,IF(AK6<=#REF!,#REF!,IF(AK6<=#REF!,#REF!,IF(AK6<=#REF!,#REF!,IF(AK6<=#REF!,#REF!,IF(AK6<=#REF!,#REF!,0.05))))))) | AV6: =AU6*AK6 | AX6: =IF(AN6<=#REF!,#REF!,IF(AN6<=#REF!,#REF!,IF(AN6<=#REF!,#REF!,IF(AN6<=#REF!,#REF!,IF(AN6<=#REF!,#REF!,IF(AN6<=#REF!,#REF!,IF(AN6<=#REF!,#REF!,0.05))))))) | AY6: =AX6*AN6 | BA6: =IF(AQ6<=#REF!,#REF!,IF(AQ6<=#REF!,#REF!,IF(AQ6<=#REF!,#REF!,IF(AQ6<=#REF!,#REF!,IF(AQ6<=#REF!,#REF!,IF(AQ6<=#REF!,#REF!,IF(AQ6<=#REF!,#REF!,0.05))))))) | BB6: =BA6*SUM(AY6,AV6,AQ6) | BD6: =IF(AT6<=#REF!,#REF!,IF(AT6<=#REF!,#REF!,IF(AT6<=#REF!,#REF!,IF(AT6<=#REF!,#REF!,IF(AT6<=#REF!,#REF!,IF(AT6<=#REF!,#REF!,IF(AT6<=#REF!,#REF!,0.05))))))) | BE6: =BD6*AT6 | BG6: =0.07*SUM(AQ6,AV6,AY6,BB6,BE6) | BI6: =SUM(BG6,BE6,BB6,AY6,AV6,AQ6) | BJ6: =SUM(BE6,BB6,AY6,AV6) | BK6: =BJ6/BI6 | BN6: 0.05 | BO6: 1000000000 | BQ6: 0.2 | BR6: 4000 | BT6: 0.22 | BU6: 19000 | BW6: -0.05 | BX6: 19000 | CA6: 3000 | CD6: =CA6 | CG6: =CA6+CD6 | CJ6: =CG6 | CK6: =IF(CA6<=BO$4,BN$4,IF(CA6<=BO$5,BN$5,IF(CA6<=BO$6,BN$6,IF(CA6<=BO$7,BN$7,IF(CA6<=BO$12,BN$12,IF(CA6<=BO$13,BN$13,IF(CA6<=BO$14,BN$14,0.05))))))) | CL6: =CK6*CA6 | CN6: =IF(CD6<=BR$4,BQ$4,IF(CD6<=BR$5,BQ$5,IF(CD6<=BR$6,BQ$6,IF(CD6<=BR$7,BQ$7,IF(CD6<=BR$12,BQ$12,IF(CD6<=BR$13,BQ$13,IF(CD6<=BR$14,BQ$14,0.05))))))) | CO6: =CN6*CD6 | CQ6: =IF(CG6<=BU$4,BT$4,IF(CG6<=BU$5,BT$5,IF(CG6<=BU$6,BT$6,IF(CG6<=BU$7,BT$7,IF(CG6<=BU$12,BT$12,IF(CG6<=BU$13,BT$13,IF(CG6<=BU$14,BT$14,0.05))))))) | CR6: =CQ6*SUM(CO6,CL6,CG6) | CT6: =IF(CJ6<=BX$4,BW$4,IF(CJ6<=BX$5,BW$5,IF(CJ6<=BX$6,BW$6,IF(CJ6<=BX$7,BW$7,IF(CJ6<=BX$12,BW$12,IF(CJ6<=BX$13,BW$13,IF(CJ6<=BX$14,BW$14,0.05))))))) | CU6: =CT6*CJ6 | CW6: =0.07*SUM(CG6,CL6,CO6,CR6,CU6) | CY6: =SUM(CW6,CU6,CR6,CO6,CL6,CG6) | CZ6: =SUM(CU6,CR6,CO6,CL6) | DA6: =CZ6/CY6
A7: Approx Start Date | AK7: 4000 | AN7: =AK7 | AQ7: =AK7+AN7 | AT7: =AQ7 | AU7: =IF(AK7<=#REF!,#REF!,IF(AK7<=#REF!,#REF!,IF(AK7<=#REF!,#REF!,IF(AK7<=#REF!,#REF!,IF(AK7<=#REF!,#REF!,IF(AK7<=#REF!,#REF!,IF(AK7<=#REF!,#REF!,0.05))))))) | AV7: =AU7*AK7 | AX7: =IF(AN7<=#REF!,#REF!,IF(AN7<=#REF!,#REF!,IF(AN7<=#REF!,#REF!,IF(AN7<=#REF!,#REF!,IF(AN7<=#REF!,#REF!,IF(AN7<=#REF!,#REF!,IF(AN7<=#REF!,#REF!,0.05))))))) | AY7: =AX7*AN7 | BA7: =IF(AQ7<=#REF!,#REF!,IF(AQ7<=#REF!,#REF!,IF(AQ7<=#REF!,#REF!,IF(AQ7<=#REF!,#REF!,IF(AQ7<=#REF!,#REF!,IF(AQ7<=#REF!,#REF!,IF(AQ7<=#REF!,#REF!,0.05))))))) | BB7: =BA7*SUM(AY7,AV7,AQ7) | BD7: =IF(AT7<=#REF!,#REF!,IF(AT7<=#REF!,#REF!,IF(AT7<=#REF!,#REF!,IF(AT7<=#REF!,#REF!,IF(AT7<=#REF!,#REF!,IF(AT7<=#REF!,#REF!,IF(AT7<=#REF!,#REF!,0.05))))))) | BE7: =BD7*AT7 | BG7: =0.07*SUM(AQ7,AV7,AY7,BB7,BE7) | BI7: =SUM(BG7,BE7,BB7,AY7,AV7,AQ7) | BJ7: =SUM(BE7,BB7,AY7,AV7) | BK7: =BJ7/BI7 | BN7: 0.05 | BO7: 1000000000 | BQ7: 0.1 | BR7: 7000 | BT7: 0.2 | BU7: 24000 | BW7: -0.05 | BX7: 34000 | CA7: 4000 | CD7: =CA7 | CG7: =CA7+CD7 | CJ7: =CG7 | CK7: =IF(CA7<=BO$4,BN$4,IF(CA7<=BO$5,BN$5,IF(CA7<=BO$6,BN$6,IF(CA7<=BO$7,BN$7,IF(CA7<=BO$12,BN$12,IF(CA7<=BO$13,BN$13,IF(CA7<=BO$14,BN$14,0.05))))))) | CL7: =CK7*CA7 | CN7: =IF(CD7<=BR$4,BQ$4,IF(CD7<=BR$5,BQ$5,IF(CD7<=BR$6,BQ$6,IF(CD7<=BR$7,BQ$7,IF(CD7<=BR$12,BQ$12,IF(CD7<=BR$13,BQ$13,IF(CD7<=BR$14,BQ$14,0.05))))))) | CO7: =CN7*CD7 | CQ7: =IF(CG7<=BU$4,BT$4,IF(CG7<=BU$5,BT$5,IF(CG7<=BU$6,BT$6,IF(CG7<=BU$7,BT$7,IF(CG7<=BU$12,BT$12,IF(CG7<=BU$13,BT$13,IF(CG7<=BU$14,BT$14,0.05))))))) | CR7: =CQ7*SUM(CO7,CL7,CG7) | CT7: =IF(CJ7<=BX$4,BW$4,IF(CJ7<=BX$5,BW$5,IF(CJ7<=BX$6,BW$6,IF(CJ7<=BX$7,BW$7,IF(CJ7<=BX$12,BW$12,IF(CJ7<=BX$13,BW$13,IF(CJ7<=BX$14,BW$14,0.05))))))) | CU7: =CT7*CJ7 | CW7: =0.07*SUM(CG7,CL7,CO7,CR7,CU7) | CY7: =SUM(CW7,CU7,CR7,CO7,CL7,CG7) | CZ7: =SUM(CU7,CR7,CO7,CL7) | DA7: =CZ7/CY7
A8: Architect
A9: Drawings Dated
A10: New / Reno:
A12: Floor System- Epoxy: | AK12: 5000 | AN12: =AK12 | AQ12: =AK12+AN12 | AT12: =AQ12 | AU12: =IF(AK12<=#REF!,#REF!,IF(AK12<=#REF!,#REF!,IF(AK12<=#REF!,#REF!,IF(AK12<=#REF!,#REF!,IF(AK12<=#REF!,#REF!,IF(AK12<=#REF!,#REF!,IF(AK12<=#REF!,#REF!,0.05))))))) | AV12: =AU12*AK12 | AX12: =IF(AN12<=#REF!,#REF!,IF(AN12<=#REF!,#REF!,IF(AN12<=#REF!,#REF!,IF(AN12<=#REF!,#REF!,IF(AN12<=#REF!,#REF!,IF(AN12<=#REF!,#REF!,IF(AN12<=#REF!,#REF!,0.05))))))) | AY12: =AX12*AN12 | BA12: =IF(AQ12<=#REF!,#REF!,IF(AQ12<=#REF!,#REF!,IF(AQ12<=#REF!,#REF!,IF(AQ12<=#REF!,#REF!,IF(AQ12<=#REF!,#REF!,IF(AQ12<=#REF!,#REF!,IF(AQ12<=#REF!,#REF!,0.05))))))) | BB12: =BA12*SUM(AY12,AV12,AQ12) | BD12: =IF(AT12<=#REF!,#REF!,IF(AT12<=#REF!,#REF!,IF(AT12<=#REF!,#REF!,IF(AT12<=#REF!,#REF!,IF(AT12<=#REF!,#REF!,IF(AT12<=#REF!,#REF!,IF(AT12<=#REF!,#REF!,0.05))))))) | BE12: =BD12*AT12 | BG12: =0.07*SUM(AQ12,AV12,AY12,BB12,BE12) | BI12: =SUM(BG12,BE12,BB12,AY12,AV12,AQ12) | BJ12: =SUM(BE12,BB12,AY12,AV12) | BK12: =BJ12/BI12 | BN12: 0.05 | BO12: 1000000000 | BQ12: 0.05 | BR12: 10000 | BT12: 0.18 | BU12: 1000000000 | BW12: -0.055 | BX12: 44000 | CA12: 5000 | CD12: =CA12 | CG12: =CA12+CD12 | CJ12: =CG12 | CK12: =IF(CA12<=BO$4,BN$4,IF(CA12<=BO$5,BN$5,IF(CA12<=BO$6,BN$6,IF(CA12<=BO$7,BN$7,IF(CA12<=BO$12,BN$12,IF(CA12<=BO$13,BN$13,IF(CA12<=BO$14,BN$14,0.05))))))) | CL12: =CK12*CA12 | CN12: =IF(CD12<=BR$4,BQ$4,IF(CD12<=BR$5,BQ$5,IF(CD12<=BR$6,BQ$6,IF(CD12<=BR$7,BQ$7,IF(CD12<=BR$12,BQ$12,IF(CD12<=BR$13,BQ$13,IF(CD12<=BR$14,BQ$14,0.05))))))) | CO12: =CN12*CD12 | CQ12: =IF(CG12<=BU$4,BT$4,IF(CG12<=BU$5,BT$5,IF(CG12<=BU$6,BT$6,IF(CG12<=BU$7,BT$7,IF(CG12<=BU$12,BT$12,IF(CG12<=BU$13,BT$13,IF(CG12<=BU$14,BT$14,0.05))))))) | CR12: =CQ12*SUM(CO12,CL12,CG12) | CT12: =IF(CJ12<=BX$4,BW$4,IF(CJ12<=BX$5,BW$5,IF(CJ12<=BX$6,BW$6,IF(CJ12<=BX$7,BW$7,IF(CJ12<=BX$12,BW$12,IF(CJ12<=BX$13,BW$13,IF(CJ12<=BX$14,BW$14,0.05))))))) | CU12: =CT12*CJ12 | CW12: =0.07*SUM(CG12,CL12,CO12,CR12,CU12) | CY12: =SUM(CW12,CU12,CR12,CO12,CL12,CG12) | CZ12: =SUM(CU12,CR12,CO12,CL12) | DA12: =CZ12/CY12
A13: Cove: | AK13: 6000 | AN13: =AK13 | AQ13: =AK13+AN13 | AT13: =AQ13 | AU13: =IF(AK13<=#REF!,#REF!,IF(AK13<=#REF!,#REF!,IF(AK13<=#REF!,#REF!,IF(AK13<=#REF!,#REF!,IF(AK13<=#REF!,#REF!,IF(AK13<=#REF!,#REF!,IF(AK13<=#REF!,#REF!,0.05))))))) | AV13: =AU13*AK13 | AX13: =IF(AN13<=#REF!,#REF!,IF(AN13<=#REF!,#REF!,IF(AN13<=#REF!,#REF!,IF(AN13<=#REF!,#REF!,IF(AN13<=#REF!,#REF!,IF(AN13<=#REF!,#REF!,IF(AN13<=#REF!,#REF!,0.05))))))) | AY13: =AX13*AN13 | BA13: =IF(AQ13<=#REF!,#REF!,IF(AQ13<=#REF!,#REF!,IF(AQ13<=#REF!,#REF!,IF(AQ13<=#REF!,#REF!,IF(AQ13<=#REF!,#REF!,IF(AQ13<=#REF!,#REF!,IF(AQ13<=#REF!,#REF!,0.05))))))) | BB13: =BA13*SUM(AY13,AV13,AQ13) | BD13: =IF(AT13<=#REF!,#REF!,IF(AT13<=#REF!,#REF!,IF(AT13<=#REF!,#REF!,IF(AT13<=#REF!,#REF!,IF(AT13<=#REF!,#REF!,IF(AT13<=#REF!,#REF!,IF(AT13<=#REF!,#REF!,0.05))))))) | BE13: =BD13*AT13 | BG13: =0.07*SUM(AQ13,AV13,AY13,BB13,BE13) | BI13: =SUM(BG13,BE13,BB13,AY13,AV13,AQ13) | BJ13: =SUM(BE13,BB13,AY13,AV13) | BK13: =BJ13/BI13 | BN13: 0.05 | BO13: 1000000000 | BQ13: 0.03 | BR13: 1000000000 | BT13: 0.18 | BU13: 1000000000 | BW13: -0.06 | BX13: 1000000000 | CA13: 6000 | CD13: =CA13 | CG13: =CA13+CD13 | CJ13: =CG13 | CK13: =IF(CA13<=BO$4,BN$4,IF(CA13<=BO$5,BN$5,IF(CA13<=BO$6,BN$6,IF(CA13<=BO$7,BN$7,IF(CA13<=BO$12,BN$12,IF(CA13<=BO$13,BN$13,IF(CA13<=BO$14,BN$14,0.05))))))) | CL13: =CK13*CA13 | CN13: =IF(CD13<=BR$4,BQ$4,IF(CD13<=BR$5,BQ$5,IF(CD13<=BR$6,BQ$6,IF(CD13<=BR$7,BQ$7,IF(CD13<=BR$12,BQ$12,IF(CD13<=BR$13,BQ$13,IF(CD13<=BR$14,BQ$14,0.05))))))) | CO13: =CN13*CD13 | CQ13: =IF(CG13<=BU$4,BT$4,IF(CG13<=BU$5,BT$5,IF(CG13<=BU$6,BT$6,IF(CG13<=BU$7,BT$7,IF(CG13<=BU$12,BT$12,IF(CG13<=BU$13,BT$13,IF(CG13<=BU$14,BT$14,0.05))))))) | CR13: =CQ13*SUM(CO13,CL13,CG13) | CT13: =IF(CJ13<=BX$4,BW$4,IF(CJ13<=BX$5,BW$5,IF(CJ13<=BX$6,BW$6,IF(CJ13<=BX$7,BW$7,IF(CJ13<=BX$12,BW$12,IF(CJ13<=BX$13,BW$13,IF(CJ13<=BX$14,BW$14,0.05))))))) | CU13: =CT13*CJ13 | CW13: =0.07*SUM(CG13,CL13,CO13,CR13,CU13) | CY13: =SUM(CW13,CU13,CR13,CO13,CL13,CG13) | CZ13: =SUM(CU13,CR13,CO13,CL13) | DA13: =CZ13/CY13
A14: ? - Walls: | AK14: 7000 | AN14: =AK14 | AQ14: =AK14+AN14 | AT14: =AQ14 | AU14: =IF(AK14<=#REF!,#REF!,IF(AK14<=#REF!,#REF!,IF(AK14<=#REF!,#REF!,IF(AK14<=#REF!,#REF!,IF(AK14<=#REF!,#REF!,IF(AK14<=#REF!,#REF!,IF(AK14<=#REF!,#REF!,0.05))))))) | AV14: =AU14*AK14 | AX14: =IF(AN14<=#REF!,#REF!,IF(AN14<=#REF!,#REF!,IF(AN14<=#REF!,#REF!,IF(AN14<=#REF!,#REF!,IF(AN14<=#REF!,#REF!,IF(AN14<=#REF!,#REF!,IF(AN14<=#REF!,#REF!,0.05))))))) | AY14: =AX14*AN14 | BA14: =IF(AQ14<=#REF!,#REF!,IF(AQ14<=#REF!,#REF!,IF(AQ14<=#REF!,#REF!,IF(AQ14<=#REF!,#REF!,IF(AQ14<=#REF!,#REF!,IF(AQ14<=#REF!,#REF!,IF(AQ14<=#REF!,#REF!,0.05))))))) | BB14: =BA14*SUM(AY14,AV14,AQ14) | BD14: =IF(AT14<=#REF!,#REF!,IF(AT14<=#REF!,#REF!,IF(AT14<=#REF!,#REF!,IF(AT14<=#REF!,#REF!,IF(AT14<=#REF!,#REF!,IF(AT14<=#REF!,#REF!,IF(AT14<=#REF!,#REF!,0.05))))))) | BE14: =BD14*AT14 | BG14: =0.07*SUM(AQ14,AV14,AY14,BB14,BE14) | BI14: =SUM(BG14,BE14,BB14,AY14,AV14,AQ14) | BJ14: =SUM(BE14,BB14,AY14,AV14) | BK14: =BJ14/BI14 | BN14: 0.05 | BO14: 1000000000 | BQ14: 0.03 | BR14: 1000000000 | BT14: 0.18 | BU14: 1000000000 | BW14: 0 | BX14: 1000000000 | CA14: 7000 | CD14: =CA14 | CG14: =CA14+CD14 | CJ14: =CG14 | CK14: =IF(CA14<=BO$4,BN$4,IF(CA14<=BO$5,BN$5,IF(CA14<=BO$6,BN$6,IF(CA14<=BO$7,BN$7,IF(CA14<=BO$12,BN$12,IF(CA14<=BO$13,BN$13,IF(CA14<=BO$14,BN$14,0.05))))))) | CL14: =CK14*CA14 | CN14: =IF(CD14<=BR$4,BQ$4,IF(CD14<=BR$5,BQ$5,IF(CD14<=BR$6,BQ$6,IF(CD14<=BR$7,BQ$7,IF(CD14<=BR$12,BQ$12,IF(CD14<=BR$13,BQ$13,IF(CD14<=BR$14,BQ$14,0.05))))))) | CO14: =CN14*CD14 | CQ14: =IF(CG14<=BU$4,BT$4,IF(CG14<=BU$5,BT$5,IF(CG14<=BU$6,BT$6,IF(CG14<=BU$7,BT$7,IF(CG14<=BU$12,BT$12,IF(CG14<=BU$13,BT$13,IF(CG14<=BU$14,BT$14,0.05))))))) | CR14: =CQ14*SUM(CO14,CL14,CG14) | CT14: =IF(CJ14<=BX$4,BW$4,IF(CJ14<=BX$5,BW$5,IF(CJ14<=BX$6,BW$6,IF(CJ14<=BX$7,BW$7,IF(CJ14<=BX$12,BW$12,IF(CJ14<=BX$13,BW$13,IF(CJ14<=BX$14,BW$14,0.05))))))) | CU14: =CT14*CJ14 | CW14: =0.07*SUM(CG14,CL14,CO14,CR14,CU14) | CY14: =SUM(CW14,CU14,CR14,CO14,CL14,CG14) | CZ14: =SUM(CU14,CR14,CO14,CL14) | DA14: =CZ14/CY14
AK15: 8000 | AN15: =AK15 | AQ15: =AK15+AN15 | AT15: =AQ15 | AU15: =IF(AK15<=#REF!,#REF!,IF(AK15<=#REF!,#REF!,IF(AK15<=#REF!,#REF!,IF(AK15<=#REF!,#REF!,IF(AK15<=#REF!,#REF!,IF(AK15<=#REF!,#REF!,IF(AK15<=#REF!,#REF!,0.05))))))) | AV15: =AU15*AK15 | AX15: =IF(AN15<=#REF!,#REF!,IF(AN15<=#REF!,#REF!,IF(AN15<=#REF!,#REF!,IF(AN15<=#REF!,#REF!,IF(AN15<=#REF!,#REF!,IF(AN15<=#REF!,#REF!,IF(AN15<=#REF!,#REF!,0.05))))))) | AY15: =AX15*AN15 | BA15: =IF(AQ15<=#REF!,#REF!,IF(AQ15<=#REF!,#REF!,IF(AQ15<=#REF!,#REF!,IF(AQ15<=#REF!,#REF!,IF(AQ15<=#REF!,#REF!,IF(AQ15<=#REF!,#REF!,IF(AQ15<=#REF!,#REF!,0.05))))))) | BB15: =BA15*SUM(AY15,AV15,AQ15) | BD15: =IF(AT15<=#REF!,#REF!,IF(AT15<=#REF!,#REF!,IF(AT15<=#REF!,#REF!,IF(AT15<=#REF!,#REF!,IF(AT15<=#REF!,#REF!,IF(AT15<=#REF!,#REF!,IF(AT15<=#REF!,#REF!,0.05))))))) | BE15: =BD15*AT15 | BG15: =0.07*SUM(AQ15,AV15,AY15,BB15,BE15) | BI15: =SUM(BG15,BE15,BB15,AY15,AV15,AQ15) | BJ15: =SUM(BE15,BB15,AY15,AV15) | BK15: =BJ15/BI15 | CA15: 8000 | CD15: =CA15 | CG15: =CA15+CD15 | CJ15: =CG15 | CK15: =IF(CA15<=BO$4,BN$4,IF(CA15<=BO$5,BN$5,IF(CA15<=BO$6,BN$6,IF(CA15<=BO$7,BN$7,IF(CA15<=BO$12,BN$12,IF(CA15<=BO$13,BN$13,IF(CA15<=BO$14,BN$14,0.05))))))) | CL15: =CK15*CA15 | CN15: =IF(CD15<=BR$4,BQ$4,IF(CD15<=BR$5,BQ$5,IF(CD15<=BR$6,BQ$6,IF(CD15<=BR$7,BQ$7,IF(CD15<=BR$12,BQ$12,IF(CD15<=BR$13,BQ$13,IF(CD15<=BR$14,BQ$14,0.05))))))) | CO15: =CN15*CD15 | CQ15: =IF(CG15<=BU$4,BT$4,IF(CG15<=BU$5,BT$5,IF(CG15<=BU$6,BT$6,IF(CG15<=BU$7,BT$7,IF(CG15<=BU$12,BT$12,IF(CG15<=BU$13,BT$13,IF(CG15<=BU$14,BT$14,0.05))))))) | CR15: =CQ15*SUM(CO15,CL15,CG15) | CT15: =IF(CJ15<=BX$4,BW$4,IF(CJ15<=BX$5,BW$5,IF(CJ15<=BX$6,BW$6,IF(CJ15<=BX$7,BW$7,IF(CJ15<=BX$12,BW$12,IF(CJ15<=BX$13,BW$13,IF(CJ15<=BX$14,BW$14,0.05))))))) | CU15: =CT15*CJ15 | CW15: =0.07*SUM(CG15,CL15,CO15,CR15,CU15) | CY15: =SUM(CW15,CU15,CR15,CO15,CL15,CG15) | CZ15: =SUM(CU15,CR15,CO15,CL15) | DA15: =CZ15/CY15
A16: Total Base Bid: | B16: =D88 | C16: $ / SF: | D16: =C88 | AK16: 9000 | AN16: =AK16 | AQ16: =AK16+AN16 | AT16: =AQ16 | AU16: =IF(AK16<=#REF!,#REF!,IF(AK16<=#REF!,#REF!,IF(AK16<=#REF!,#REF!,IF(AK16<=#REF!,#REF!,IF(AK16<=#REF!,#REF!,IF(AK16<=#REF!,#REF!,IF(AK16<=#REF!,#REF!,0.05))))))) | AV16: =AU16*AK16 | AX16: =IF(AN16<=#REF!,#REF!,IF(AN16<=#REF!,#REF!,IF(AN16<=#REF!,#REF!,IF(AN16<=#REF!,#REF!,IF(AN16<=#REF!,#REF!,IF(AN16<=#REF!,#REF!,IF(AN16<=#REF!,#REF!,0.05))))))) | AY16: =AX16*AN16 | BA16: =IF(AQ16<=#REF!,#REF!,IF(AQ16<=#REF!,#REF!,IF(AQ16<=#REF!,#REF!,IF(AQ16<=#REF!,#REF!,IF(AQ16<=#REF!,#REF!,IF(AQ16<=#REF!,#REF!,IF(AQ16<=#REF!,#REF!,0.05))))))) | BB16: =BA16*SUM(AY16,AV16,AQ16) | BD16: =IF(AT16<=#REF!,#REF!,IF(AT16<=#REF!,#REF!,IF(AT16<=#REF!,#REF!,IF(AT16<=#REF!,#REF!,IF(AT16<=#REF!,#REF!,IF(AT16<=#REF!,#REF!,IF(AT16<=#REF!,#REF!,0.05))))))) | BE16: =BD16*AT16 | BG16: =0.07*SUM(AQ16,AV16,AY16,BB16,BE16) | BI16: =SUM(BG16,BE16,BB16,AY16,AV16,AQ16) | BJ16: =SUM(BE16,BB16,AY16,AV16) | BK16: =BJ16/BI16 | CA16: 9000 | CD16: =CA16 | CG16: =CA16+CD16 | CJ16: =CG16 | CK16: =IF(CA16<=BO$4,BN$4,IF(CA16<=BO$5,BN$5,IF(CA16<=BO$6,BN$6,IF(CA16<=BO$7,BN$7,IF(CA16<=BO$12,BN$12,IF(CA16<=BO$13,BN$13,IF(CA16<=BO$14,BN$14,0.05))))))) | CL16: =CK16*CA16 | CN16: =IF(CD16<=BR$4,BQ$4,IF(CD16<=BR$5,BQ$5,IF(CD16<=BR$6,BQ$6,IF(CD16<=BR$7,BQ$7,IF(CD16<=BR$12,BQ$12,IF(CD16<=BR$13,BQ$13,IF(CD16<=BR$14,BQ$14,0.05))))))) | CO16: =CN16*CD16 | CQ16: =IF(CG16<=BU$4,BT$4,IF(CG16<=BU$5,BT$5,IF(CG16<=BU$6,BT$6,IF(CG16<=BU$7,BT$7,IF(CG16<=BU$12,BT$12,IF(CG16<=BU$13,BT$13,IF(CG16<=BU$14,BT$14,0.05))))))) | CR16: =CQ16*SUM(CO16,CL16,CG16) | CT16: =IF(CJ16<=BX$4,BW$4,IF(CJ16<=BX$5,BW$5,IF(CJ16<=BX$6,BW$6,IF(CJ16<=BX$7,BW$7,IF(CJ16<=BX$12,BW$12,IF(CJ16<=BX$13,BW$13,IF(CJ16<=BX$14,BW$14,0.05))))))) | CU16: =CT16*CJ16 | CW16: =0.07*SUM(CG16,CL16,CO16,CR16,CU16) | CY16: =SUM(CW16,CU16,CR16,CO16,CL16,CG16) | CZ16: =SUM(CU16,CR16,CO16,CL16) | DA16: =CZ16/CY16
A17: MATERIAL - Patch | B17: Quantity | C17: Cost | D17: Total | H17: Standard Add's | I17: Cost / Unit | J17: SF -or- LF | K17: Total | AK17: 10000 | AN17: =AK17 | AQ17: =AK17+AN17 | AT17: =AQ17 | AU17: =IF(AK17<=#REF!,#REF!,IF(AK17<=#REF!,#REF!,IF(AK17<=#REF!,#REF!,IF(AK17<=#REF!,#REF!,IF(AK17<=#REF!,#REF!,IF(AK17<=#REF!,#REF!,IF(AK17<=#REF!,#REF!,0.05))))))) | AV17: =AU17*AK17 | AX17: =IF(AN17<=#REF!,#REF!,IF(AN17<=#REF!,#REF!,IF(AN17<=#REF!,#REF!,IF(AN17<=#REF!,#REF!,IF(AN17<=#REF!,#REF!,IF(AN17<=#REF!,#REF!,IF(AN17<=#REF!,#REF!,0.05))))))) | AY17: =AX17*AN17 | BA17: =IF(AQ17<=#REF!,#REF!,IF(AQ17<=#REF!,#REF!,IF(AQ17<=#REF!,#REF!,IF(AQ17<=#REF!,#REF!,IF(AQ17<=#REF!,#REF!,IF(AQ17<=#REF!,#REF!,IF(AQ17<=#REF!,#REF!,0.05))))))) | BB17: =BA17*SUM(AY17,AV17,AQ17) | BD17: =IF(AT17<=#REF!,#REF!,IF(AT17<=#REF!,#REF!,IF(AT17<=#REF!,#REF!,IF(AT17<=#REF!,#REF!,IF(AT17<=#REF!,#REF!,IF(AT17<=#REF!,#REF!,IF(AT17<=#REF!,#REF!,0.05))))))) | BE17: =BD17*AT17 | BG17: =0.07*SUM(AQ17,AV17,AY17,BB17,BE17) | BI17: =SUM(BG17,BE17,BB17,AY17,AV17,AQ17) | BJ17: =SUM(BE17,BB17,AY17,AV17) | BK17: =BJ17/BI17 | CA17: 10000 | CD17: =CA17 | CG17: =CA17+CD17 | CJ17: =CG17 | CK17: =IF(CA17<=BO$4,BN$4,IF(CA17<=BO$5,BN$5,IF(CA17<=BO$6,BN$6,IF(CA17<=BO$7,BN$7,IF(CA17<=BO$12,BN$12,IF(CA17<=BO$13,BN$13,IF(CA17<=BO$14,BN$14,0.05))))))) | CL17: =CK17*CA17 | CN17: =IF(CD17<=BR$4,BQ$4,IF(CD17<=BR$5,BQ$5,IF(CD17<=BR$6,BQ$6,IF(CD17<=BR$7,BQ$7,IF(CD17<=BR$12,BQ$12,IF(CD17<=BR$13,BQ$13,IF(CD17<=BR$14,BQ$14,0.05))))))) | CO17: =CN17*CD17 | CQ17: =IF(CG17<=BU$4,BT$4,IF(CG17<=BU$5,BT$5,IF(CG17<=BU$6,BT$6,IF(CG17<=BU$7,BT$7,IF(CG17<=BU$12,BT$12,IF(CG17<=BU$13,BT$13,IF(CG17<=BU$14,BT$14,0.05))))))) | CR17: =CQ17*SUM(CO17,CL17,CG17) | CT17: =IF(CJ17<=BX$4,BW$4,IF(CJ17<=BX$5,BW$5,IF(CJ17<=BX$6,BW$6,IF(CJ17<=BX$7,BW$7,IF(CJ17<=BX$12,BW$12,IF(CJ17<=BX$13,BW$13,IF(CJ17<=BX$14,BW$14,0.05))))))) | CU17: =CT17*CJ17 | CW17: =0.07*SUM(CG17,CL17,CO17,CR17,CU17) | CY17: =SUM(CW17,CU17,CR17,CO17,CL17,CG17) | CZ17: =SUM(CU17,CR17,CO17,CL17) | DA17: =CZ17/CY17
A18: system 1 | B18: =E20 | C18: 0.1 | D18: =B18*C18 | H18: Ram Board | I18: =IF(J18<=1000,validation!$R$4,IF(J18<1500,validation!$R$6,IF(J18<2000,validation!$R$8,IF(J18<2500,validation!$R$10,IF(J18<=3000,validation!$R$12,IF(J18<3500,validation!$R$14,IF(J18<4000,validation!$R$16,IF(J18<5000,validation!$R$18,validation!$R$20)))))))) | J18: =B45 | K18: =ROUNDUP((I18*J18),0) | L18: LF | M18: $ / LF | AK18: 11000 | AN18: =AK18 | AQ18: =AK18+AN18 | AT18: =AQ18 | AU18: =IF(AK18<=#REF!,#REF!,IF(AK18<=#REF!,#REF!,IF(AK18<=#REF!,#REF!,IF(AK18<=#REF!,#REF!,IF(AK18<=#REF!,#REF!,IF(AK18<=#REF!,#REF!,IF(AK18<=#REF!,#REF!,0.05))))))) | AV18: =AU18*AK18 | AX18: =IF(AN18<=#REF!,#REF!,IF(AN18<=#REF!,#REF!,IF(AN18<=#REF!,#REF!,IF(AN18<=#REF!,#REF!,IF(AN18<=#REF!,#REF!,IF(AN18<=#REF!,#REF!,IF(AN18<=#REF!,#REF!,0.05))))))) | AY18: =AX18*AN18 | BA18: =IF(AQ18<=#REF!,#REF!,IF(AQ18<=#REF!,#REF!,IF(AQ18<=#REF!,#REF!,IF(AQ18<=#REF!,#REF!,IF(AQ18<=#REF!,#REF!,IF(AQ18<=#REF!,#REF!,IF(AQ18<=#REF!,#REF!,0.05))))))) | BB18: =BA18*SUM(AY18,AV18,AQ18) | BD18: =IF(AT18<=#REF!,#REF!,IF(AT18<=#REF!,#REF!,IF(AT18<=#REF!,#REF!,IF(AT18<=#REF!,#REF!,IF(AT18<=#REF!,#REF!,IF(AT18<=#REF!,#REF!,IF(AT18<=#REF!,#REF!,0.05))))))) | BE18: =BD18*AT18 | BG18: =0.07*SUM(AQ18,AV18,AY18,BB18,BE18) | BI18: =SUM(BG18,BE18,BB18,AY18,AV18,AQ18) | BJ18: =SUM(BE18,BB18,AY18,AV18) | BK18: =BJ18/BI18 | CA18: 11000 | CD18: =CA18 | CG18: =CA18+CD18 | CJ18: =CG18 | CK18: =IF(CA18<=BO$4,BN$4,IF(CA18<=BO$5,BN$5,IF(CA18<=BO$6,BN$6,IF(CA18<=BO$7,BN$7,IF(CA18<=BO$12,BN$12,IF(CA18<=BO$13,BN$13,IF(CA18<=BO$14,BN$14,0.05))))))) | CL18: =CK18*CA18 | CN18: =IF(CD18<=BR$4,BQ$4,IF(CD18<=BR$5,BQ$5,IF(CD18<=BR$6,BQ$6,IF(CD18<=BR$7,BQ$7,IF(CD18<=BR$12,BQ$12,IF(CD18<=BR$13,BQ$13,IF(CD18<=BR$14,BQ$14,0.05))))))) | CO18: =CN18*CD18 | CQ18: =IF(CG18<=BU$4,BT$4,IF(CG18<=BU$5,BT$5,IF(CG18<=BU$6,BT$6,IF(CG18<=BU$7,BT$7,IF(CG18<=BU$12,BT$12,IF(CG18<=BU$13,BT$13,IF(CG18<=BU$14,BT$14,0.05))))))) | CR18: =CQ18*SUM(CO18,CL18,CG18) | CT18: =IF(CJ18<=BX$4,BW$4,IF(CJ18<=BX$5,BW$5,IF(CJ18<=BX$6,BW$6,IF(CJ18<=BX$7,BW$7,IF(CJ18<=BX$12,BW$12,IF(CJ18<=BX$13,BW$13,IF(CJ18<=BX$14,BW$14,0.05))))))) | CU18: =CT18*CJ18 | CW18: =0.07*SUM(CG18,CL18,CO18,CR18,CU18) | CY18: =SUM(CW18,CU18,CR18,CO18,CL18,CG18) | CZ18: =SUM(CU18,CR18,CO18,CL18) | DA18: =CZ18/CY18
A19: system 2 | B19: =E24 | C19: =C18 | D19: =B19*C19 | H19: Joint Filler | I19: =IF(J19<=1000,validation!$U$4,IF(J19<1500,validation!$U$6,IF(J19<2000,validation!$U$8,IF(J19<2500,validation!$U$10,IF(J19<=3000,validation!$U$12,IF(J19<3500,validation!$U$14,IF(J19<4000,validation!$U$16,IF(J19<5000,validation!$U$18,validation!$U$20)))))))) | J19: =B45 | K19: =ROUNDUP((I19*J19),0) | L19: =0.2*J19 | M19: =K19/L19 | N19: *Double for removal of existing soft joints | AK19: 12000 | AN19: =AK19 | AQ19: =AK19+AN19 | AT19: =AQ19 | AU19: =IF(AK19<=#REF!,#REF!,IF(AK19<=#REF!,#REF!,IF(AK19<=#REF!,#REF!,IF(AK19<=#REF!,#REF!,IF(AK19<=#REF!,#REF!,IF(AK19<=#REF!,#REF!,IF(AK19<=#REF!,#REF!,0.05))))))) | AV19: =AU19*AK19 | AX19: =IF(AN19<=#REF!,#REF!,IF(AN19<=#REF!,#REF!,IF(AN19<=#REF!,#REF!,IF(AN19<=#REF!,#REF!,IF(AN19<=#REF!,#REF!,IF(AN19<=#REF!,#REF!,IF(AN19<=#REF!,#REF!,0.05))))))) | AY19: =AX19*AN19 | BA19: =IF(AQ19<=#REF!,#REF!,IF(AQ19<=#REF!,#REF!,IF(AQ19<=#REF!,#REF!,IF(AQ19<=#REF!,#REF!,IF(AQ19<=#REF!,#REF!,IF(AQ19<=#REF!,#REF!,IF(AQ19<=#REF!,#REF!,0.05))))))) | BB19: =BA19*SUM(AY19,AV19,AQ19) | BD19: =IF(AT19<=#REF!,#REF!,IF(AT19<=#REF!,#REF!,IF(AT19<=#REF!,#REF!,IF(AT19<=#REF!,#REF!,IF(AT19<=#REF!,#REF!,IF(AT19<=#REF!,#REF!,IF(AT19<=#REF!,#REF!,0.05))))))) | BE19: =BD19*AT19 | BG19: =0.07*SUM(AQ19,AV19,AY19,BB19,BE19) | BI19: =SUM(BG19,BE19,BB19,AY19,AV19,AQ19) | BJ19: =SUM(BE19,BB19,AY19,AV19) | BK19: =BJ19/BI19 | CA19: 12000 | CD19: =CA19 | CG19: =CA19+CD19 | CJ19: =CG19 | CK19: =IF(CA19<=BO$4,BN$4,IF(CA19<=BO$5,BN$5,IF(CA19<=BO$6,BN$6,IF(CA19<=BO$7,BN$7,IF(CA19<=BO$12,BN$12,IF(CA19<=BO$13,BN$13,IF(CA19<=BO$14,BN$14,0.05))))))) | CL19: =CK19*CA19 | CN19: =IF(CD19<=BR$4,BQ$4,IF(CD19<=BR$5,BQ$5,IF(CD19<=BR$6,BQ$6,IF(CD19<=BR$7,BQ$7,IF(CD19<=BR$12,BQ$12,IF(CD19<=BR$13,BQ$13,IF(CD19<=BR$14,BQ$14,0.05))))))) | CO19: =CN19*CD19 | CQ19: =IF(CG19<=BU$4,BT$4,IF(CG19<=BU$5,BT$5,IF(CG19<=BU$6,BT$6,IF(CG19<=BU$7,BT$7,IF(CG19<=BU$12,BT$12,IF(CG19<=BU$13,BT$13,IF(CG19<=BU$14,BT$14,0.05))))))) | CR19: =CQ19*SUM(CO19,CL19,CG19) | CT19: =IF(CJ19<=BX$4,BW$4,IF(CJ19<=BX$5,BW$5,IF(CJ19<=BX$6,BW$6,IF(CJ19<=BX$7,BW$7,IF(CJ19<=BX$12,BW$12,IF(CJ19<=BX$13,BW$13,IF(CJ19<=BX$14,BW$14,0.05))))))) | CU19: =CT19*CJ19 | CW19: =0.07*SUM(CG19,CL19,CO19,CR19,CU19) | CY19: =SUM(CW19,CU19,CR19,CO19,CL19,CG19) | CZ19: =SUM(CU19,CR19,CO19,CL19) | DA19: =CZ19/CY19
A20: MATERIAL - Epoxy Liquids | E20: 0 | F20: SF -- System 1 | H20: 4" Rubber Cove (/LF) | I20: =IF(J20<=100,validation!$R$24,IF(J20<150,validation!$R$26,IF(J20<200,validation!$R$28,IF(J20<250,validation!$R$30,IF(J20<=300,validation!$R$32,IF(J20<350,validation!$R$34,IF(J20<400,validation!$R$36,IF(J20<500,validation!$R$38,validation!$R$40)))))))) | J20: =E34+E37 | K20: =ROUNDUP((I20*J20),0) | AK20: 13000 | AN20: =AK20 | AQ20: =AK20+AN20 | AT20: =AQ20 | AU20: =IF(AK20<=#REF!,#REF!,IF(AK20<=#REF!,#REF!,IF(AK20<=#REF!,#REF!,IF(AK20<=#REF!,#REF!,IF(AK20<=#REF!,#REF!,IF(AK20<=#REF!,#REF!,IF(AK20<=#REF!,#REF!,0.05))))))) | AV20: =AU20*AK20 | AX20: =IF(AN20<=#REF!,#REF!,IF(AN20<=#REF!,#REF!,IF(AN20<=#REF!,#REF!,IF(AN20<=#REF!,#REF!,IF(AN20<=#REF!,#REF!,IF(AN20<=#REF!,#REF!,IF(AN20<=#REF!,#REF!,0.05))))))) | AY20: =AX20*AN20 | BA20: =IF(AQ20<=#REF!,#REF!,IF(AQ20<=#REF!,#REF!,IF(AQ20<=#REF!,#REF!,IF(AQ20<=#REF!,#REF!,IF(AQ20<=#REF!,#REF!,IF(AQ20<=#REF!,#REF!,IF(AQ20<=#REF!,#REF!,0.05))))))) | BB20: =BA20*SUM(AY20,AV20,AQ20) | BD20: =IF(AT20<=#REF!,#REF!,IF(AT20<=#REF!,#REF!,IF(AT20<=#REF!,#REF!,IF(AT20<=#REF!,#REF!,IF(AT20<=#REF!,#REF!,IF(AT20<=#REF!,#REF!,IF(AT20<=#REF!,#REF!,0.05))))))) | BE20: =BD20*AT20 | BG20: =0.07*SUM(AQ20,AV20,AY20,BB20,BE20) | BI20: =SUM(BG20,BE20,BB20,AY20,AV20,AQ20) | BJ20: =SUM(BE20,BB20,AY20,AV20) | BK20: =BJ20/BI20 | CA20: 13000 | CD20: =CA20 | CG20: =CA20+CD20 | CJ20: =CG20 | CK20: =IF(CA20<=BO$4,BN$4,IF(CA20<=BO$5,BN$5,IF(CA20<=BO$6,BN$6,IF(CA20<=BO$7,BN$7,IF(CA20<=BO$12,BN$12,IF(CA20<=BO$13,BN$13,IF(CA20<=BO$14,BN$14,0.05))))))) | CL20: =CK20*CA20 | CN20: =IF(CD20<=BR$4,BQ$4,IF(CD20<=BR$5,BQ$5,IF(CD20<=BR$6,BQ$6,IF(CD20<=BR$7,BQ$7,IF(CD20<=BR$12,BQ$12,IF(CD20<=BR$13,BQ$13,IF(CD20<=BR$14,BQ$14,0.05))))))) | CO20: =CN20*CD20 | CQ20: =IF(CG20<=BU$4,BT$4,IF(CG20<=BU$5,BT$5,IF(CG20<=BU$6,BT$6,IF(CG20<=BU$7,BT$7,IF(CG20<=BU$12,BT$12,IF(CG20<=BU$13,BT$13,IF(CG20<=BU$14,BT$14,0.05))))))) | CR20: =CQ20*SUM(CO20,CL20,CG20) | CT20: =IF(CJ20<=BX$4,BW$4,IF(CJ20<=BX$5,BW$5,IF(CJ20<=BX$6,BW$6,IF(CJ20<=BX$7,BW$7,IF(CJ20<=BX$12,BW$12,IF(CJ20<=BX$13,BW$13,IF(CJ20<=BX$14,BW$14,0.05))))))) | CU20: =CT20*CJ20 | CW20: =0.07*SUM(CG20,CL20,CO20,CR20,CU20) | CY20: =SUM(CW20,CU20,CR20,CO20,CL20,CG20) | CZ20: =SUM(CU20,CR20,CO20,CL20) | DA20: =CZ20/CY20
A21: Primer Options | C21: Liquids | D21: =IF(A21=B162,F162,IF(A21=B163,F163,IF(A21=B164,F164,IF(A21=B165,F165,0)))) | H21: 6" Rubber Cove (/LF) | I21: =IF(J20<=100,validation!$U$24,IF(J20<150,validation!$U$26,IF(J20<200,validation!$U$28,IF(J20<250,validation!$U$30,IF(J20<=300,validation!$U$32,IF(J20<350,validation!$U$34,IF(J20<400,validation!$U$36,IF(J20<500,validation!$U$38,validation!$U$40)))))))) | J21: =E34+E37 | K21: =ROUNDUP((I21*J21),0) | M21: Epoxy: | N21: ='Stnd Alts'!E243 | O21: Mock-Up* | AK21: 14000 | AN21: =AK21 | AQ21: =AK21+AN21 | AT21: =AQ21 | AU21: =IF(AK21<=#REF!,#REF!,IF(AK21<=#REF!,#REF!,IF(AK21<=#REF!,#REF!,IF(AK21<=#REF!,#REF!,IF(AK21<=#REF!,#REF!,IF(AK21<=#REF!,#REF!,IF(AK21<=#REF!,#REF!,0.05))))))) | AV21: =AU21*AK21 | AX21: =IF(AN21<=#REF!,#REF!,IF(AN21<=#REF!,#REF!,IF(AN21<=#REF!,#REF!,IF(AN21<=#REF!,#REF!,IF(AN21<=#REF!,#REF!,IF(AN21<=#REF!,#REF!,IF(AN21<=#REF!,#REF!,0.05))))))) | AY21: =AX21*AN21 | BA21: =IF(AQ21<=#REF!,#REF!,IF(AQ21<=#REF!,#REF!,IF(AQ21<=#REF!,#REF!,IF(AQ21<=#REF!,#REF!,IF(AQ21<=#REF!,#REF!,IF(AQ21<=#REF!,#REF!,IF(AQ21<=#REF!,#REF!,0.05))))))) | BB21: =BA21*SUM(AY21,AV21,AQ21) | BD21: =IF(AT21<=#REF!,#REF!,IF(AT21<=#REF!,#REF!,IF(AT21<=#REF!,#REF!,IF(AT21<=#REF!,#REF!,IF(AT21<=#REF!,#REF!,IF(AT21<=#REF!,#REF!,IF(AT21<=#REF!,#REF!,0.05))))))) | BE21: =BD21*AT21 | BG21: =0.07*SUM(AQ21,AV21,AY21,BB21,BE21) | BI21: =SUM(BG21,BE21,BB21,AY21,AV21,AQ21) | BJ21: =SUM(BE21,BB21,AY21,AV21) | BK21: =BJ21/BI21 | CA21: 14000 | CD21: =CA21 | CG21: =CA21+CD21 | CJ21: =CG21 | CK21: =IF(CA21<=BO$4,BN$4,IF(CA21<=BO$5,BN$5,IF(CA21<=BO$6,BN$6,IF(CA21<=BO$7,BN$7,IF(CA21<=BO$12,BN$12,IF(CA21<=BO$13,BN$13,IF(CA21<=BO$14,BN$14,0.05))))))) | CL21: =CK21*CA21 | CN21: =IF(CD21<=BR$4,BQ$4,IF(CD21<=BR$5,BQ$5,IF(CD21<=BR$6,BQ$6,IF(CD21<=BR$7,BQ$7,IF(CD21<=BR$12,BQ$12,IF(CD21<=BR$13,BQ$13,IF(CD21<=BR$14,BQ$14,0.05))))))) | CO21: =CN21*CD21 | CQ21: =IF(CG21<=BU$4,BT$4,IF(CG21<=BU$5,BT$5,IF(CG21<=BU$6,BT$6,IF(CG21<=BU$7,BT$7,IF(CG21<=BU$12,BT$12,IF(CG21<=BU$13,BT$13,IF(CG21<=BU$14,BT$14,0.05))))))) | CR21: =CQ21*SUM(CO21,CL21,CG21) | CT21: =IF(CJ21<=BX$4,BW$4,IF(CJ21<=BX$5,BW$5,IF(CJ21<=BX$6,BW$6,IF(CJ21<=BX$7,BW$7,IF(CJ21<=BX$12,BW$12,IF(CJ21<=BX$13,BW$13,IF(CJ21<=BX$14,BW$14,0.05))))))) | CU21: =CT21*CJ21 | CW21: =0.07*SUM(CG21,CL21,CO21,CR21,CU21) | CY21: =SUM(CW21,CU21,CR21,CO21,CL21,CG21) | CZ21: =SUM(CU21,CR21,CO21,CL21) | DA21: =CZ21/CY21
A22: System 1 Options | C22: Liquids | D22: =IF(A22=R181,F175,IF(A22=R182,F182,IF(A22=R183,F188,IF(A22=R184,F197,IF(A22=R185,F205,IF(A22=R186,F213,IF(A22=R187,F221,IF(A22=R188,F227,IF(A22=R189,F237,IF(A22=R190,F245,IF(A22=R191,F254,IF(A22=R192,F264,IF(A22=R193,F271,IF(A22=R194,F279,IF(A22=R195,F286,0))))))))))))))) | H22: 4" Line Striping (/LF) | I22: =IF(J22<=100,validation!$R$44,IF(J22<150,validation!$R$46,IF(J22<200,validation!$R$48,IF(J22<250,validation!$R$50,IF(J22<=300,validation!$R$52,IF(J22<350,validation!$R$54,IF(J22<400,validation!$R$56,IF(J22<500,validation!$R$58,validation!$R$60)))))))) | J22: 0 | K22: =ROUNDUP((I22*J22),0) | M22: **In Town** | N22: ='Stnd Alts'!E145 | O22: Mob Fee* | P22: *see "Stnd Alts" tab | AK22: 15000 | AN22: =AK22 | AQ22: =AK22+AN22 | AT22: =AQ22 | AU22: =IF(AK22<=#REF!,#REF!,IF(AK22<=#REF!,#REF!,IF(AK22<=#REF!,#REF!,IF(AK22<=#REF!,#REF!,IF(AK22<=#REF!,#REF!,IF(AK22<=#REF!,#REF!,IF(AK22<=#REF!,#REF!,0.05))))))) | AV22: =AU22*AK22 | AX22: =IF(AN22<=#REF!,#REF!,IF(AN22<=#REF!,#REF!,IF(AN22<=#REF!,#REF!,IF(AN22<=#REF!,#REF!,IF(AN22<=#REF!,#REF!,IF(AN22<=#REF!,#REF!,IF(AN22<=#REF!,#REF!,0.05))))))) | AY22: =AX22*AN22 | BA22: =IF(AQ22<=#REF!,#REF!,IF(AQ22<=#REF!,#REF!,IF(AQ22<=#REF!,#REF!,IF(AQ22<=#REF!,#REF!,IF(AQ22<=#REF!,#REF!,IF(AQ22<=#REF!,#REF!,IF(AQ22<=#REF!,#REF!,0.05))))))) | BB22: =BA22*SUM(AY22,AV22,AQ22) | BD22: =IF(AT22<=#REF!,#REF!,IF(AT22<=#REF!,#REF!,IF(AT22<=#REF!,#REF!,IF(AT22<=#REF!,#REF!,IF(AT22<=#REF!,#REF!,IF(AT22<=#REF!,#REF!,IF(AT22<=#REF!,#REF!,0.05))))))) | BE22: =BD22*AT22 | BG22: =0.07*SUM(AQ22,AV22,AY22,BB22,BE22) | BI22: =SUM(BG22,BE22,BB22,AY22,AV22,AQ22) | BJ22: =SUM(BE22,BB22,AY22,AV22) | BK22: =BJ22/BI22 | CA22: 15000 | CD22: =CA22 | CG22: =CA22+CD22 | CJ22: =CG22 | CK22: =IF(CA22<=BO$4,BN$4,IF(CA22<=BO$5,BN$5,IF(CA22<=BO$6,BN$6,IF(CA22<=BO$7,BN$7,IF(CA22<=BO$12,BN$12,IF(CA22<=BO$13,BN$13,IF(CA22<=BO$14,BN$14,0.05))))))) | CL22: =CK22*CA22 | CN22: =IF(CD22<=BR$4,BQ$4,IF(CD22<=BR$5,BQ$5,IF(CD22<=BR$6,BQ$6,IF(CD22<=BR$7,BQ$7,IF(CD22<=BR$12,BQ$12,IF(CD22<=BR$13,BQ$13,IF(CD22<=BR$14,BQ$14,0.05))))))) | CO22: =CN22*CD22 | CQ22: =IF(CG22<=BU$4,BT$4,IF(CG22<=BU$5,BT$5,IF(CG22<=BU$6,BT$6,IF(CG22<=BU$7,BT$7,IF(CG22<=BU$12,BT$12,IF(CG22<=BU$13,BT$13,IF(CG22<=BU$14,BT$14,0.05))))))) | CR22: =CQ22*SUM(CO22,CL22,CG22) | CT22: =IF(CJ22<=BX$4,BW$4,IF(CJ22<=BX$5,BW$5,IF(CJ22<=BX$6,BW$6,IF(CJ22<=BX$7,BW$7,IF(CJ22<=BX$12,BW$12,IF(CJ22<=BX$13,BW$13,IF(CJ22<=BX$14,BW$14,0.05))))))) | CU22: =CT22*CJ22 | CW22: =0.07*SUM(CG22,CL22,CO22,CR22,CU22) | CY22: =SUM(CW22,CU22,CR22,CO22,CL22,CG22) | CZ22: =SUM(CU22,CR22,CO22,CL22) | DA22: =CZ22/CY22
D23: =B23*C23 | H23: 6" Line Striping (/LF) | I23: =IF(J22<=100,validation!$U$44,IF(J22<150,validation!$U$46,IF(J22<200,validation!$U$48,IF(J22<250,validation!$U$50,IF(J22<=300,validation!$U$52,IF(J22<350,validation!$U$54,IF(J22<400,validation!$U$56,IF(J22<500,validation!$U$58,validation!$U$60)))))))) | J23: 0 | K23: =ROUNDUP((I23*J23),0) | AK23: 16000 | AN23: =AK23 | AQ23: =AK23+AN23 | AT23: =AQ23 | AU23: =IF(AK23<=#REF!,#REF!,IF(AK23<=#REF!,#REF!,IF(AK23<=#REF!,#REF!,IF(AK23<=#REF!,#REF!,IF(AK23<=#REF!,#REF!,IF(AK23<=#REF!,#REF!,IF(AK23<=#REF!,#REF!,0.05))))))) | AV23: =AU23*AK23 | AX23: =IF(AN23<=#REF!,#REF!,IF(AN23<=#REF!,#REF!,IF(AN23<=#REF!,#REF!,IF(AN23<=#REF!,#REF!,IF(AN23<=#REF!,#REF!,IF(AN23<=#REF!,#REF!,IF(AN23<=#REF!,#REF!,0.05))))))) | AY23: =AX23*AN23 | BA23: =IF(AQ23<=#REF!,#REF!,IF(AQ23<=#REF!,#REF!,IF(AQ23<=#REF!,#REF!,IF(AQ23<=#REF!,#REF!,IF(AQ23<=#REF!,#REF!,IF(AQ23<=#REF!,#REF!,IF(AQ23<=#REF!,#REF!,0.05))))))) | BB23: =BA23*SUM(AY23,AV23,AQ23) | BD23: =IF(AT23<=#REF!,#REF!,IF(AT23<=#REF!,#REF!,IF(AT23<=#REF!,#REF!,IF(AT23<=#REF!,#REF!,IF(AT23<=#REF!,#REF!,IF(AT23<=#REF!,#REF!,IF(AT23<=#REF!,#REF!,0.05))))))) | BE23: =BD23*AT23 | BG23: =0.07*SUM(AQ23,AV23,AY23,BB23,BE23) | BI23: =SUM(BG23,BE23,BB23,AY23,AV23,AQ23) | BJ23: =SUM(BE23,BB23,AY23,AV23) | BK23: =BJ23/BI23 | CA23: 16000 | CD23: =CA23 | CG23: =CA23+CD23 | CJ23: =CG23 | CK23: =IF(CA23<=BO$4,BN$4,IF(CA23<=BO$5,BN$5,IF(CA23<=BO$6,BN$6,IF(CA23<=BO$7,BN$7,IF(CA23<=BO$12,BN$12,IF(CA23<=BO$13,BN$13,IF(CA23<=BO$14,BN$14,0.05))))))) | CL23: =CK23*CA23 | CN23: =IF(CD23<=BR$4,BQ$4,IF(CD23<=BR$5,BQ$5,IF(CD23<=BR$6,BQ$6,IF(CD23<=BR$7,BQ$7,IF(CD23<=BR$12,BQ$12,IF(CD23<=BR$13,BQ$13,IF(CD23<=BR$14,BQ$14,0.05))))))) | CO23: =CN23*CD23 | CQ23: =IF(CG23<=BU$4,BT$4,IF(CG23<=BU$5,BT$5,IF(CG23<=BU$6,BT$6,IF(CG23<=BU$7,BT$7,IF(CG23<=BU$12,BT$12,IF(CG23<=BU$13,BT$13,IF(CG23<=BU$14,BT$14,0.05))))))) | CR23: =CQ23*SUM(CO23,CL23,CG23) | CT23: =IF(CJ23<=BX$4,BW$4,IF(CJ23<=BX$5,BW$5,IF(CJ23<=BX$6,BW$6,IF(CJ23<=BX$7,BW$7,IF(CJ23<=BX$12,BW$12,IF(CJ23<=BX$13,BW$13,IF(CJ23<=BX$14,BW$14,0.05))))))) | CU23: =CT23*CJ23 | CW23: =0.07*SUM(CG23,CL23,CO23,CR23,CU23) | CY23: =SUM(CW23,CU23,CR23,CO23,CL23,CG23) | CZ23: =SUM(CU23,CR23,CO23,CL23) | DA23: =CZ23/CY23
A24: MATERIAL - Epoxy Liquids | E24: 0 | F24: SF -- System 2 | H24: Patch: Gallons CoveRez | I24: 86 | J24: =(SUM(D18:D19)) | K24: =ROUND(J24/I24,0) | L24: # of Gallons (if CoveRez) | N24: AT satin clr + Grit = | O24: =AT_Clear_Satin_w_Grit | P24: <---broken cell, can't change "Defined Name" | AK24: 17000 | AN24: =AK24 | AQ24: =AK24+AN24 | AT24: =AQ24 | AU24: =IF(AK24<=#REF!,#REF!,IF(AK24<=#REF!,#REF!,IF(AK24<=#REF!,#REF!,IF(AK24<=#REF!,#REF!,IF(AK24<=#REF!,#REF!,IF(AK24<=#REF!,#REF!,IF(AK24<=#REF!,#REF!,0.05))))))) | AV24: =AU24*AK24 | AX24: =IF(AN24<=#REF!,#REF!,IF(AN24<=#REF!,#REF!,IF(AN24<=#REF!,#REF!,IF(AN24<=#REF!,#REF!,IF(AN24<=#REF!,#REF!,IF(AN24<=#REF!,#REF!,IF(AN24<=#REF!,#REF!,0.05))))))) | AY24: =AX24*AN24 | BA24: =IF(AQ24<=#REF!,#REF!,IF(AQ24<=#REF!,#REF!,IF(AQ24<=#REF!,#REF!,IF(AQ24<=#REF!,#REF!,IF(AQ24<=#REF!,#REF!,IF(AQ24<=#REF!,#REF!,IF(AQ24<=#REF!,#REF!,0.05))))))) | BB24: =BA24*SUM(AY24,AV24,AQ24) | BD24: =IF(AT24<=#REF!,#REF!,IF(AT24<=#REF!,#REF!,IF(AT24<=#REF!,#REF!,IF(AT24<=#REF!,#REF!,IF(AT24<=#REF!,#REF!,IF(AT24<=#REF!,#REF!,IF(AT24<=#REF!,#REF!,0.05))))))) | BE24: =BD24*AT24 | BG24: =0.07*SUM(AQ24,AV24,AY24,BB24,BE24) | BI24: =SUM(BG24,BE24,BB24,AY24,AV24,AQ24) | BJ24: =SUM(BE24,BB24,AY24,AV24) | BK24: =BJ24/BI24 | CA24: 17000 | CD24: =CA24 | CG24: =CA24+CD24 | CJ24: =CG24 | CK24: =IF(CA24<=BO$4,BN$4,IF(CA24<=BO$5,BN$5,IF(CA24<=BO$6,BN$6,IF(CA24<=BO$7,BN$7,IF(CA24<=BO$12,BN$12,IF(CA24<=BO$13,BN$13,IF(CA24<=BO$14,BN$14,0.05))))))) | CL24: =CK24*CA24 | CN24: =IF(CD24<=BR$4,BQ$4,IF(CD24<=BR$5,BQ$5,IF(CD24<=BR$6,BQ$6,IF(CD24<=BR$7,BQ$7,IF(CD24<=BR$12,BQ$12,IF(CD24<=BR$13,BQ$13,IF(CD24<=BR$14,BQ$14,0.05))))))) | CO24: =CN24*CD24 | CQ24: =IF(CG24<=BU$4,BT$4,IF(CG24<=BU$5,BT$5,IF(CG24<=BU$6,BT$6,IF(CG24<=BU$7,BT$7,IF(CG24<=BU$12,BT$12,IF(CG24<=BU$13,BT$13,IF(CG24<=BU$14,BT$14,0.05))))))) | CR24: =CQ24*SUM(CO24,CL24,CG24) | CT24: =IF(CJ24<=BX$4,BW$4,IF(CJ24<=BX$5,BW$5,IF(CJ24<=BX$6,BW$6,IF(CJ24<=BX$7,BW$7,IF(CJ24<=BX$12,BW$12,IF(CJ24<=BX$13,BW$13,IF(CJ24<=BX$14,BW$14,0.05))))))) | CU24: =CT24*CJ24 | CW24: =0.07*SUM(CG24,CL24,CO24,CR24,CU24) | CY24: =SUM(CW24,CU24,CR24,CO24,CL24,CG24) | CZ24: =SUM(CU24,CR24,CO24,CL24) | DA24: =CZ24/CY24
A25: Primer Options | C25: Liquids | D25: =IF(A25=AB162,AF162,IF(A25=AB163,AF163,IF(A25=AB164,AF164,IF(A25=AB165,AF165,IF(A25=AB166,AF166,IF(A25=AB167,AF167,0)))))) | H25: Patch: Kits of WR | I25: 59 | J25: =(SUM(D18:D19)) | K25: =ROUND(J25/I25,0) | L25: # of Kits (if WR) | O25: Takoff Tab | P25: sf | Q25: lf | R25: extra cell | S25: extra cell | T25: extra cell | AK25: 18000 | AN25: =AK25 | AQ25: =AK25+AN25 | AT25: =AQ25 | AU25: =IF(AK25<=#REF!,#REF!,IF(AK25<=#REF!,#REF!,IF(AK25<=#REF!,#REF!,IF(AK25<=#REF!,#REF!,IF(AK25<=#REF!,#REF!,IF(AK25<=#REF!,#REF!,IF(AK25<=#REF!,#REF!,0.05))))))) | AV25: =AU25*AK25 | AX25: =IF(AN25<=#REF!,#REF!,IF(AN25<=#REF!,#REF!,IF(AN25<=#REF!,#REF!,IF(AN25<=#REF!,#REF!,IF(AN25<=#REF!,#REF!,IF(AN25<=#REF!,#REF!,IF(AN25<=#REF!,#REF!,0.05))))))) | AY25: =AX25*AN25 | BA25: =IF(AQ25<=#REF!,#REF!,IF(AQ25<=#REF!,#REF!,IF(AQ25<=#REF!,#REF!,IF(AQ25<=#REF!,#REF!,IF(AQ25<=#REF!,#REF!,IF(AQ25<=#REF!,#REF!,IF(AQ25<=#REF!,#REF!,0.05))))))) | BB25: =BA25*SUM(AY25,AV25,AQ25) | BD25: =IF(AT25<=#REF!,#REF!,IF(AT25<=#REF!,#REF!,IF(AT25<=#REF!,#REF!,IF(AT25<=#REF!,#REF!,IF(AT25<=#REF!,#REF!,IF(AT25<=#REF!,#REF!,IF(AT25<=#REF!,#REF!,0.05))))))) | BE25: =BD25*AT25 | BG25: =0.07*SUM(AQ25,AV25,AY25,BB25,BE25) | BI25: =SUM(BG25,BE25,BB25,AY25,AV25,AQ25) | BJ25: =SUM(BE25,BB25,AY25,AV25) | BK25: =BJ25/BI25 | CA25: 18000 | CD25: =CA25 | CG25: =CA25+CD25 | CJ25: =CG25 | CK25: =IF(CA25<=BO$4,BN$4,IF(CA25<=BO$5,BN$5,IF(CA25<=BO$6,BN$6,IF(CA25<=BO$7,BN$7,IF(CA25<=BO$12,BN$12,IF(CA25<=BO$13,BN$13,IF(CA25<=BO$14,BN$14,0.05))))))) | CL25: =CK25*CA25 | CN25: =IF(CD25<=BR$4,BQ$4,IF(CD25<=BR$5,BQ$5,IF(CD25<=BR$6,BQ$6,IF(CD25<=BR$7,BQ$7,IF(CD25<=BR$12,BQ$12,IF(CD25<=BR$13,BQ$13,IF(CD25<=BR$14,BQ$14,0.05))))))) | CO25: =CN25*CD25 | CQ25: =IF(CG25<=BU$4,BT$4,IF(CG25<=BU$5,BT$5,IF(CG25<=BU$6,BT$6,IF(CG25<=BU$7,BT$7,IF(CG25<=BU$12,BT$12,IF(CG25<=BU$13,BT$13,IF(CG25<=BU$14,BT$14,0.05))))))) | CR25: =CQ25*SUM(CO25,CL25,CG25) | CT25: =IF(CJ25<=BX$4,BW$4,IF(CJ25<=BX$5,BW$5,IF(CJ25<=BX$6,BW$6,IF(CJ25<=BX$7,BW$7,IF(CJ25<=BX$12,BW$12,IF(CJ25<=BX$13,BW$13,IF(CJ25<=BX$14,BW$14,0.05))))))) | CU25: =CT25*CJ25 | CW25: =0.07*SUM(CG25,CL25,CO25,CR25,CU25) | CY25: =SUM(CW25,CU25,CR25,CO25,CL25,CG25) | CZ25: =SUM(CU25,CR25,CO25,CL25) | DA25: =CZ25/CY25
A26: System 2 Options / Walls (scroll down) | C26: Liquids | D26: =IF(A26=AR181,AF175,IF(A26=AR182,AF182,IF(A26=AR183,AF188,IF(A26=AR184,AF197,IF(A26=AR185,AF205,IF(A26=AR186,AF213,IF(A26=AR187,AF221,IF(A26=AR188,AF227,IF(A26=AR189,AF237,IF(A26=AR190,AF245,IF(A26=AR191,AF254,IF(A26=AR192,AF264,IF(A26=AR193,AF271,IF(A26=AR194,AF279,IF(A26=AR195,AF286,IF(A26=AR198,AF297,IF(A26=AR199,AF308,IF(A26=AR200,AF316,IF(A26=AR201,AF324,IF(A26=AR202,AF331,IF(A26=AR203,AF339,0))))))))))))))))))))) | O26: =Takeoff!B14 | P26: =Takeoff!C14 | Q26: =Takeoff!D14 | R26: =Takeoff!E14 | S26: =Takeoff!F14 | T26: =Takeoff!G14 | AK26: 19000 | AN26: =AK26 | AQ26: =AK26+AN26 | AT26: =AQ26 | AU26: =IF(AK26<=#REF!,#REF!,IF(AK26<=#REF!,#REF!,IF(AK26<=#REF!,#REF!,IF(AK26<=#REF!,#REF!,IF(AK26<=#REF!,#REF!,IF(AK26<=#REF!,#REF!,IF(AK26<=#REF!,#REF!,0.05))))))) | AV26: =AU26*AK26 | AX26: =IF(AN26<=#REF!,#REF!,IF(AN26<=#REF!,#REF!,IF(AN26<=#REF!,#REF!,IF(AN26<=#REF!,#REF!,IF(AN26<=#REF!,#REF!,IF(AN26<=#REF!,#REF!,IF(AN26<=#REF!,#REF!,0.05))))))) | AY26: =AX26*AN26 | BA26: =IF(AQ26<=#REF!,#REF!,IF(AQ26<=#REF!,#REF!,IF(AQ26<=#REF!,#REF!,IF(AQ26<=#REF!,#REF!,IF(AQ26<=#REF!,#REF!,IF(AQ26<=#REF!,#REF!,IF(AQ26<=#REF!,#REF!,0.05))))))) | BB26: =BA26*SUM(AY26,AV26,AQ26) | BD26: =IF(AT26<=#REF!,#REF!,IF(AT26<=#REF!,#REF!,IF(AT26<=#REF!,#REF!,IF(AT26<=#REF!,#REF!,IF(AT26<=#REF!,#REF!,IF(AT26<=#REF!,#REF!,IF(AT26<=#REF!,#REF!,0.05))))))) | BE26: =BD26*AT26 | BG26: =0.07*SUM(AQ26,AV26,AY26,BB26,BE26) | BI26: =SUM(BG26,BE26,BB26,AY26,AV26,AQ26) | BJ26: =SUM(BE26,BB26,AY26,AV26) | BK26: =BJ26/BI26 | CA26: 19000 | CD26: =CA26 | CG26: =CA26+CD26 | CJ26: =CG26 | CK26: =IF(CA26<=BO$4,BN$4,IF(CA26<=BO$5,BN$5,IF(CA26<=BO$6,BN$6,IF(CA26<=BO$7,BN$7,IF(CA26<=BO$12,BN$12,IF(CA26<=BO$13,BN$13,IF(CA26<=BO$14,BN$14,0.05))))))) | CL26: =CK26*CA26 | CN26: =IF(CD26<=BR$4,BQ$4,IF(CD26<=BR$5,BQ$5,IF(CD26<=BR$6,BQ$6,IF(CD26<=BR$7,BQ$7,IF(CD26<=BR$12,BQ$12,IF(CD26<=BR$13,BQ$13,IF(CD26<=BR$14,BQ$14,0.05))))))) | CO26: =CN26*CD26 | CQ26: =IF(CG26<=BU$4,BT$4,IF(CG26<=BU$5,BT$5,IF(CG26<=BU$6,BT$6,IF(CG26<=BU$7,BT$7,IF(CG26<=BU$12,BT$12,IF(CG26<=BU$13,BT$13,IF(CG26<=BU$14,BT$14,0.05))))))) | CR26: =CQ26*SUM(CO26,CL26,CG26) | CT26: =IF(CJ26<=BX$4,BW$4,IF(CJ26<=BX$5,BW$5,IF(CJ26<=BX$6,BW$6,IF(CJ26<=BX$7,BW$7,IF(CJ26<=BX$12,BW$12,IF(CJ26<=BX$13,BW$13,IF(CJ26<=BX$14,BW$14,0.05))))))) | CU26: =CT26*CJ26 | CW26: =0.07*SUM(CG26,CL26,CO26,CR26,CU26) | CY26: =SUM(CW26,CU26,CR26,CO26,CL26,CG26) | CZ26: =SUM(CU26,CR26,CO26,CL26) | DA26: =CZ26/CY26
D27: =B27*C27 | O27: =Takeoff!I14 | P27: =Takeoff!J14 | Q27: =Takeoff!K14 | R27: =Takeoff!L14 | S27: =Takeoff!M14 | T27: =Takeoff!N14 | AW27: 20000 | AZ27: =AW27 | BC27: =AW27+AZ27 | BF27: =BC27 | BG27: =IF(AW27<=#REF!,#REF!,IF(AW27<=#REF!,#REF!,IF(AW27<=#REF!,#REF!,IF(AW27<=#REF!,#REF!,IF(AW27<=#REF!,#REF!,IF(AW27<=#REF!,#REF!,IF(AW27<=#REF!,#REF!,0.05))))))) | BH27: =BG27*AW27 | BJ27: =IF(AZ27<=#REF!,#REF!,IF(AZ27<=#REF!,#REF!,IF(AZ27<=#REF!,#REF!,IF(AZ27<=#REF!,#REF!,IF(AZ27<=#REF!,#REF!,IF(AZ27<=#REF!,#REF!,IF(AZ27<=#REF!,#REF!,0.05))))))) | BK27: =BJ27*AZ27 | BM27: =IF(BC27<=#REF!,#REF!,IF(BC27<=#REF!,#REF!,IF(BC27<=#REF!,#REF!,IF(BC27<=#REF!,#REF!,IF(BC27<=#REF!,#REF!,IF(BC27<=#REF!,#REF!,IF(BC27<=#REF!,#REF!,0.05))))))) | BN27: =BM27*SUM(BK27,BH27,BC27) | BP27: =IF(BF27<=#REF!,#REF!,IF(BF27<=#REF!,#REF!,IF(BF27<=#REF!,#REF!,IF(BF27<=#REF!,#REF!,IF(BF27<=#REF!,#REF!,IF(BF27<=#REF!,#REF!,IF(BF27<=#REF!,#REF!,0.05))))))) | BQ27: =BP27*BF27 | BS27: =0.07*SUM(BC27,BH27,BK27,BN27,BQ27) | BU27: =SUM(BS27,BQ27,BN27,BK27,BH27,BC27) | BV27: =SUM(BQ27,BN27,BK27,BH27) | BW27: =BV27/BU27 | CM27: 20000 | CP27: =CM27 | CS27: =CM27+CP27 | CV27: =CS27 | CW27: =IF(CM27<=BO$4,BN$4,IF(CM27<=BO$5,BN$5,IF(CM27<=BO$6,BN$6,IF(CM27<=BO$7,BN$7,IF(CM27<=BO$12,BN$12,IF(CM27<=BO$13,BN$13,IF(CM27<=BO$14,BN$14,0.05))))))) | CX27: =CW27*CM27 | CZ27: =IF(CP27<=BR$4,BQ$4,IF(CP27<=BR$5,BQ$5,IF(CP27<=BR$6,BQ$6,IF(CP27<=BR$7,BQ$7,IF(CP27<=BR$12,BQ$12,IF(CP27<=BR$13,BQ$13,IF(CP27<=BR$14,BQ$14,0.05))))))) | DA27: =CZ27*CP27 | DC27: =IF(CS27<=BU$4,BT$4,IF(CS27<=BU$5,BT$5,IF(CS27<=BU$6,BT$6,IF(CS27<=BU$7,BT$7,IF(CS27<=BU$12,BT$12,IF(CS27<=BU$13,BT$13,IF(CS27<=BU$14,BT$14,0.05))))))) | DD27: =DC27*SUM(DA27,CX27,CS27) | DF27: =IF(CV27<=BX$4,BW$4,IF(CV27<=BX$5,BW$5,IF(CV27<=BX$6,BW$6,IF(CV27<=BX$7,BW$7,IF(CV27<=BX$12,BW$12,IF(CV27<=BX$13,BW$13,IF(CV27<=BX$14,BW$14,0.05))))))) | DG27: =DF27*CV27 | DI27: =0.07*SUM(CS27,CX27,DA27,DD27,DG27) | DK27: =SUM(DI27,DG27,DD27,DA27,CX27,CS27) | DL27: =SUM(DG27,DD27,DA27,CX27) | DM27: =DL27/DK27
D28: =B28*C28 | O28: =Takeoff!P14 | P28: =Takeoff!Q14 | Q28: =Takeoff!R14 | R28: =Takeoff!S14 | S28: =Takeoff!T14 | T28: =Takeoff!U14 | AW28: 21000 | AZ28: =AW28 | BC28: =AW28+AZ28 | BF28: =BC28 | BG28: =IF(AW28<=#REF!,#REF!,IF(AW28<=#REF!,#REF!,IF(AW28<=#REF!,#REF!,IF(AW28<=#REF!,#REF!,IF(AW28<=#REF!,#REF!,IF(AW28<=#REF!,#REF!,IF(AW28<=#REF!,#REF!,0.05))))))) | BH28: =BG28*AW28 | BJ28: =IF(AZ28<=#REF!,#REF!,IF(AZ28<=#REF!,#REF!,IF(AZ28<=#REF!,#REF!,IF(AZ28<=#REF!,#REF!,IF(AZ28<=#REF!,#REF!,IF(AZ28<=#REF!,#REF!,IF(AZ28<=#REF!,#REF!,0.05))))))) | BK28: =BJ28*AZ28 | BM28: =IF(BC28<=#REF!,#REF!,IF(BC28<=#REF!,#REF!,IF(BC28<=#REF!,#REF!,IF(BC28<=#REF!,#REF!,IF(BC28<=#REF!,#REF!,IF(BC28<=#REF!,#REF!,IF(BC28<=#REF!,#REF!,0.05))))))) | BN28: =BM28*SUM(BK28,BH28,BC28) | BP28: =IF(BF28<=#REF!,#REF!,IF(BF28<=#REF!,#REF!,IF(BF28<=#REF!,#REF!,IF(BF28<=#REF!,#REF!,IF(BF28<=#REF!,#REF!,IF(BF28<=#REF!,#REF!,IF(BF28<=#REF!,#REF!,0.05))))))) | BQ28: =BP28*BF28 | BS28: =0.07*SUM(BC28,BH28,BK28,BN28,BQ28) | BU28: =SUM(BS28,BQ28,BN28,BK28,BH28,BC28) | BV28: =SUM(BQ28,BN28,BK28,BH28) | BW28: =BV28/BU28 | CM28: 21000 | CP28: =CM28 | CS28: =CM28+CP28 | CV28: =CS28 | CW28: =IF(CM28<=BO$4,BN$4,IF(CM28<=BO$5,BN$5,IF(CM28<=BO$6,BN$6,IF(CM28<=BO$7,BN$7,IF(CM28<=BO$12,BN$12,IF(CM28<=BO$13,BN$13,IF(CM28<=BO$14,BN$14,0.05))))))) | CX28: =CW28*CM28 | CZ28: =IF(CP28<=BR$4,BQ$4,IF(CP28<=BR$5,BQ$5,IF(CP28<=BR$6,BQ$6,IF(CP28<=BR$7,BQ$7,IF(CP28<=BR$12,BQ$12,IF(CP28<=BR$13,BQ$13,IF(CP28<=BR$14,BQ$14,0.05))))))) | DA28: =CZ28*CP28 | DC28: =IF(CS28<=BU$4,BT$4,IF(CS28<=BU$5,BT$5,IF(CS28<=BU$6,BT$6,IF(CS28<=BU$7,BT$7,IF(CS28<=BU$12,BT$12,IF(CS28<=BU$13,BT$13,IF(CS28<=BU$14,BT$14,0.05))))))) | DD28: =DC28*SUM(DA28,CX28,CS28) | DF28: =IF(CV28<=BX$4,BW$4,IF(CV28<=BX$5,BW$5,IF(CV28<=BX$6,BW$6,IF(CV28<=BX$7,BW$7,IF(CV28<=BX$12,BW$12,IF(CV28<=BX$13,BW$13,IF(CV28<=BX$14,BW$14,0.05))))))) | DG28: =DF28*CV28 | DI28: =0.07*SUM(CS28,CX28,DA28,DD28,DG28) | DK28: =SUM(DI28,DG28,DD28,DA28,CX28,CS28) | DL28: =SUM(DG28,DD28,DA28,CX28) | DM28: =DL28/DK28
A29: MATERIAL - Extras | O29: =Takeoff!I3 | P29: =Takeoff!J3 | Q29: =Takeoff!K3 | R29: =Takeoff!L3 | S29: =Takeoff!M3 | T29: =Takeoff!N3 | AW29: 22000 | AZ29: =AW29 | BC29: =AW29+AZ29 | BF29: =BC29 | BG29: =IF(AW29<=#REF!,#REF!,IF(AW29<=#REF!,#REF!,IF(AW29<=#REF!,#REF!,IF(AW29<=#REF!,#REF!,IF(AW29<=#REF!,#REF!,IF(AW29<=#REF!,#REF!,IF(AW29<=#REF!,#REF!,0.05))))))) | BH29: =BG29*AW29 | BJ29: =IF(AZ29<=#REF!,#REF!,IF(AZ29<=#REF!,#REF!,IF(AZ29<=#REF!,#REF!,IF(AZ29<=#REF!,#REF!,IF(AZ29<=#REF!,#REF!,IF(AZ29<=#REF!,#REF!,IF(AZ29<=#REF!,#REF!,0.05))))))) | BK29: =BJ29*AZ29 | BM29: =IF(BC29<=#REF!,#REF!,IF(BC29<=#REF!,#REF!,IF(BC29<=#REF!,#REF!,IF(BC29<=#REF!,#REF!,IF(BC29<=#REF!,#REF!,IF(BC29<=#REF!,#REF!,IF(BC29<=#REF!,#REF!,0.05))))))) | BN29: =BM29*SUM(BK29,BH29,BC29) | BP29: =IF(BF29<=#REF!,#REF!,IF(BF29<=#REF!,#REF!,IF(BF29<=#REF!,#REF!,IF(BF29<=#REF!,#REF!,IF(BF29<=#REF!,#REF!,IF(BF29<=#REF!,#REF!,IF(BF29<=#REF!,#REF!,0.05))))))) | BQ29: =BP29*BF29 | BS29: =0.07*SUM(BC29,BH29,BK29,BN29,BQ29) | BU29: =SUM(BS29,BQ29,BN29,BK29,BH29,BC29) | BV29: =SUM(BQ29,BN29,BK29,BH29) | BW29: =BV29/BU29 | CM29: 22000 | CP29: =CM29 | CS29: =CM29+CP29 | CV29: =CS29 | CW29: =IF(CM29<=BO$4,BN$4,IF(CM29<=BO$5,BN$5,IF(CM29<=BO$6,BN$6,IF(CM29<=BO$7,BN$7,IF(CM29<=BO$12,BN$12,IF(CM29<=BO$13,BN$13,IF(CM29<=BO$14,BN$14,0.05))))))) | CX29: =CW29*CM29 | CZ29: =IF(CP29<=BR$4,BQ$4,IF(CP29<=BR$5,BQ$5,IF(CP29<=BR$6,BQ$6,IF(CP29<=BR$7,BQ$7,IF(CP29<=BR$12,BQ$12,IF(CP29<=BR$13,BQ$13,IF(CP29<=BR$14,BQ$14,0.05))))))) | DA29: =CZ29*CP29 | DC29: =IF(CS29<=BU$4,BT$4,IF(CS29<=BU$5,BT$5,IF(CS29<=BU$6,BT$6,IF(CS29<=BU$7,BT$7,IF(CS29<=BU$12,BT$12,IF(CS29<=BU$13,BT$13,IF(CS29<=BU$14,BT$14,0.05))))))) | DD29: =DC29*SUM(DA29,CX29,CS29) | DF29: =IF(CV29<=BX$4,BW$4,IF(CV29<=BX$5,BW$5,IF(CV29<=BX$6,BW$6,IF(CV29<=BX$7,BW$7,IF(CV29<=BX$12,BW$12,IF(CV29<=BX$13,BW$13,IF(CV29<=BX$14,BW$14,0.05))))))) | DG29: =DF29*CV29 | DI29: =0.07*SUM(CS29,CX29,DA29,DD29,DG29) | DK29: =SUM(DI29,DG29,DD29,DA29,CX29,CS29) | DL29: =SUM(DG29,DD29,DA29,CX29) | DM29: =DL29/DK29
A30: =A22 | C30: other | D30: =IF(A30=R181,P174,IF(A30=R182,P180,IF(A30=R183,P187,IF(A30=R184,P195,IF(A30=R185,P203,IF(A30=R186,P211,IF(A30=R187,P219,IF(A30=R188,P226,IF(A30=R189,P235,IF(A30=R190,P243,IF(A30=R191,P251,IF(A30=R192,P262,IF(A30=R193,P269,IF(A30=R194,P278,IF(A30=R195,P286,0))))))))))))))) | E30: silica, flake (MACRO/micro), quartz | AW30: 23000 | AZ30: =AW30 | BC30: =AW30+AZ30 | BF30: =BC30 | BG30: =IF(AW30<=#REF!,#REF!,IF(AW30<=#REF!,#REF!,IF(AW30<=#REF!,#REF!,IF(AW30<=#REF!,#REF!,IF(AW30<=#REF!,#REF!,IF(AW30<=#REF!,#REF!,IF(AW30<=#REF!,#REF!,0.05))))))) | BH30: =BG30*AW30 | BJ30: =IF(AZ30<=#REF!,#REF!,IF(AZ30<=#REF!,#REF!,IF(AZ30<=#REF!,#REF!,IF(AZ30<=#REF!,#REF!,IF(AZ30<=#REF!,#REF!,IF(AZ30<=#REF!,#REF!,IF(AZ30<=#REF!,#REF!,0.05))))))) | BK30: =BJ30*AZ30 | BM30: =IF(BC30<=#REF!,#REF!,IF(BC30<=#REF!,#REF!,IF(BC30<=#REF!,#REF!,IF(BC30<=#REF!,#REF!,IF(BC30<=#REF!,#REF!,IF(BC30<=#REF!,#REF!,IF(BC30<=#REF!,#REF!,0.05))))))) | BN30: =BM30*SUM(BK30,BH30,BC30) | BP30: =IF(BF30<=#REF!,#REF!,IF(BF30<=#REF!,#REF!,IF(BF30<=#REF!,#REF!,IF(BF30<=#REF!,#REF!,IF(BF30<=#REF!,#REF!,IF(BF30<=#REF!,#REF!,IF(BF30<=#REF!,#REF!,0.05))))))) | BQ30: =BP30*BF30 | BS30: =0.07*SUM(BC30,BH30,BK30,BN30,BQ30) | BU30: =SUM(BS30,BQ30,BN30,BK30,BH30,BC30) | BV30: =SUM(BQ30,BN30,BK30,BH30) | BW30: =BV30/BU30 | CM30: 23000 | CP30: =CM30 | CS30: =CM30+CP30 | CV30: =CS30 | CW30: =IF(CM30<=BO$4,BN$4,IF(CM30<=BO$5,BN$5,IF(CM30<=BO$6,BN$6,IF(CM30<=BO$7,BN$7,IF(CM30<=BO$12,BN$12,IF(CM30<=BO$13,BN$13,IF(CM30<=BO$14,BN$14,0.05))))))) | CX30: =CW30*CM30 | CZ30: =IF(CP30<=BR$4,BQ$4,IF(CP30<=BR$5,BQ$5,IF(CP30<=BR$6,BQ$6,IF(CP30<=BR$7,BQ$7,IF(CP30<=BR$12,BQ$12,IF(CP30<=BR$13,BQ$13,IF(CP30<=BR$14,BQ$14,0.05))))))) | DA30: =CZ30*CP30 | DC30: =IF(CS30<=BU$4,BT$4,IF(CS30<=BU$5,BT$5,IF(CS30<=BU$6,BT$6,IF(CS30<=BU$7,BT$7,IF(CS30<=BU$12,BT$12,IF(CS30<=BU$13,BT$13,IF(CS30<=BU$14,BT$14,0.05))))))) | DD30: =DC30*SUM(DA30,CX30,CS30) | DF30: =IF(CV30<=BX$4,BW$4,IF(CV30<=BX$5,BW$5,IF(CV30<=BX$6,BW$6,IF(CV30<=BX$7,BW$7,IF(CV30<=BX$12,BW$12,IF(CV30<=BX$13,BW$13,IF(CV30<=BX$14,BW$14,0.05))))))) | DG30: =DF30*CV30 | DI30: =0.07*SUM(CS30,CX30,DA30,DD30,DG30) | DK30: =SUM(DI30,DG30,DD30,DA30,CX30,CS30) | DL30: =SUM(DG30,DD30,DA30,CX30) | DM30: =DL30/DK30
A31: =A26 | C31: other | D31: =IF(A31=AR181,AP174,IF(A31=AR182,AP180,IF(A31=AR183,AP187,IF(A31=AR184,AP195,IF(A31=AR185,AP203,IF(A31=AR186,AP211,IF(A31=AR187,AP219,IF(A31=AR188,AP226,IF(A31=AR189,AP235,IF(A31=AR190,AP243,IF(A31=AR191,AP251,IF(A31=AR192,AP262,IF(A31=AR193,AP269,IF(A31=AR194,AP278,IF(A31=AR195,AP286,IF(A31=AR198,AP296,IF(A31=AR199,AP306,IF(A31=AR200,AP314,IF(A31=AR201,AQ324,IF(A31=AR202,AQ330,IF(A31=AR203,AP336,0))))))))))))))))))))) | E31: silica, flake (MACRO/micro), quartz | O31: Cant Cove Calculator (must be a 45° Angle):
D32: =B32*C32 | O32: h2/1.5 = Ratio to 6" cove w/ cap (1/8" thick)
D33: =B33*C33 | G33: ? Yes / No ? | H33: Special Transitions ? | I33: "Nat. Guard" = 8' @ ~$130 ea. ($16.25 /lf.) | O33: =(P33*P33)/1.5 | Q33: Height of Cant Cove
A34: MATERIAL - Cove | E34: 0 | F34: LF -- System 1 | O34: =P34*O33 | Q34: Total Resin + Hardner
A35: Cove 1 Options | C35: Liquids | D35: =IF(A35=S125,F125,IF(A35=S126,F130,IF(A35=S127,F135,IF(A35=S128,F141,IF(A35=S129,F147,IF(A35=S130,F152,IF(A35=S131,P125,IF(A35=S132,P130,IF(A35=S133,P135,IF(A35=S134,P141,IF(A35=S135,P147,IF(A35=S136,P152,0)))))))))))) | E35: =B13 | O35: =P35*O33 | Q35: Total Aggregate | AW35: 24000 | AZ35: =AW35 | BC35: =AW35+AZ35 | BF35: =BC35 | BG35: =IF(AW35<=#REF!,#REF!,IF(AW35<=#REF!,#REF!,IF(AW35<=#REF!,#REF!,IF(AW35<=#REF!,#REF!,IF(AW35<=#REF!,#REF!,IF(AW35<=#REF!,#REF!,IF(AW35<=#REF!,#REF!,0.05))))))) | BH35: =BG35*AW35 | BJ35: =IF(AZ35<=#REF!,#REF!,IF(AZ35<=#REF!,#REF!,IF(AZ35<=#REF!,#REF!,IF(AZ35<=#REF!,#REF!,IF(AZ35<=#REF!,#REF!,IF(AZ35<=#REF!,#REF!,IF(AZ35<=#REF!,#REF!,0.05))))))) | BK35: =BJ35*AZ35 | BM35: =IF(BC35<=#REF!,#REF!,IF(BC35<=#REF!,#REF!,IF(BC35<=#REF!,#REF!,IF(BC35<=#REF!,#REF!,IF(BC35<=#REF!,#REF!,IF(BC35<=#REF!,#REF!,IF(BC35<=#REF!,#REF!,0.05))))))) | BN35: =BM35*SUM(BK35,BH35,BC35) | BP35: =IF(BF35<=#REF!,#REF!,IF(BF35<=#REF!,#REF!,IF(BF35<=#REF!,#REF!,IF(BF35<=#REF!,#REF!,IF(BF35<=#REF!,#REF!,IF(BF35<=#REF!,#REF!,IF(BF35<=#REF!,#REF!,0.05))))))) | BQ35: =BP35*BF35 | BS35: =0.07*SUM(BC35,BH35,BK35,BN35,BQ35) | BU35: =SUM(BS35,BQ35,BN35,BK35,BH35,BC35) | BV35: =SUM(BQ35,BN35,BK35,BH35) | BW35: =BV35/BU35 | CM35: 24000 | CP35: =CM35 | CS35: =CM35+CP35 | CV35: =CS35 | CW35: =IF(CM35<=BO$4,BN$4,IF(CM35<=BO$5,BN$5,IF(CM35<=BO$6,BN$6,IF(CM35<=BO$7,BN$7,IF(CM35<=BO$12,BN$12,IF(CM35<=BO$13,BN$13,IF(CM35<=BO$14,BN$14,0.05))))))) | CX35: =CW35*CM35 | CZ35: =IF(CP35<=BR$4,BQ$4,IF(CP35<=BR$5,BQ$5,IF(CP35<=BR$6,BQ$6,IF(CP35<=BR$7,BQ$7,IF(CP35<=BR$12,BQ$12,IF(CP35<=BR$13,BQ$13,IF(CP35<=BR$14,BQ$14,0.05))))))) | DA35: =CZ35*CP35 | DC35: =IF(CS35<=BU$4,BT$4,IF(CS35<=BU$5,BT$5,IF(CS35<=BU$6,BT$6,IF(CS35<=BU$7,BT$7,IF(CS35<=BU$12,BT$12,IF(CS35<=BU$13,BT$13,IF(CS35<=BU$14,BT$14,0.05))))))) | DD35: =DC35*SUM(DA35,CX35,CS35) | DF35: =IF(CV35<=BX$4,BW$4,IF(CV35<=BX$5,BW$5,IF(CV35<=BX$6,BW$6,IF(CV35<=BX$7,BW$7,IF(CV35<=BX$12,BW$12,IF(CV35<=BX$13,BW$13,IF(CV35<=BX$14,BW$14,0.05))))))) | DG35: =DF35*CV35 | DI35: =0.07*SUM(CS35,CX35,DA35,DD35,DG35) | DK35: =SUM(DI35,DG35,DD35,DA35,CX35,CS35) | DL35: =SUM(DG35,DD35,DA35,CX35) | DM35: =DL35/DK35
C36: Sand &/or Cap | D36: =IF(A35=S125,F126,IF(A35=S126,F131,IF(A35=S127,H137,IF(A35=S128,H143,IF(A35=S129,F148,IF(A35=S130,H154,IF(A35=S131,0,IF(A35=S132,0,IF(A35=S133,P136,IF(A35=S134,P142,IF(A35=S135,0,IF(A35=S136,P153,0)))))))))))) | O36: =P36*O33 | Q36: WR | AW36: 25000 | AZ36: =AW36 | BC36: =AW36+AZ36 | BF36: =BC36 | BG36: =IF(AW36<=#REF!,#REF!,IF(AW36<=#REF!,#REF!,IF(AW36<=#REF!,#REF!,IF(AW36<=#REF!,#REF!,IF(AW36<=#REF!,#REF!,IF(AW36<=#REF!,#REF!,IF(AW36<=#REF!,#REF!,0.05))))))) | BH36: =BG36*AW36 | BJ36: =IF(AZ36<=#REF!,#REF!,IF(AZ36<=#REF!,#REF!,IF(AZ36<=#REF!,#REF!,IF(AZ36<=#REF!,#REF!,IF(AZ36<=#REF!,#REF!,IF(AZ36<=#REF!,#REF!,IF(AZ36<=#REF!,#REF!,0.05))))))) | BK36: =BJ36*AZ36 | BM36: =IF(BC36<=#REF!,#REF!,IF(BC36<=#REF!,#REF!,IF(BC36<=#REF!,#REF!,IF(BC36<=#REF!,#REF!,IF(BC36<=#REF!,#REF!,IF(BC36<=#REF!,#REF!,IF(BC36<=#REF!,#REF!,0.05))))))) | BN36: =BM36*SUM(BK36,BH36,BC36) | BP36: =IF(BF36<=#REF!,#REF!,IF(BF36<=#REF!,#REF!,IF(BF36<=#REF!,#REF!,IF(BF36<=#REF!,#REF!,IF(BF36<=#REF!,#REF!,IF(BF36<=#REF!,#REF!,IF(BF36<=#REF!,#REF!,0.05))))))) | BQ36: =BP36*BF36 | BS36: =0.07*SUM(BC36,BH36,BK36,BN36,BQ36) | BU36: =SUM(BS36,BQ36,BN36,BK36,BH36,BC36) | BV36: =SUM(BQ36,BN36,BK36,BH36) | BW36: =BV36/BU36 | CM36: 25000 | CP36: =CM36 | CS36: =CM36+CP36 | CV36: =CS36 | CW36: =IF(CM36<=BO$4,BN$4,IF(CM36<=BO$5,BN$5,IF(CM36<=BO$6,BN$6,IF(CM36<=BO$7,BN$7,IF(CM36<=BO$12,BN$12,IF(CM36<=BO$13,BN$13,IF(CM36<=BO$14,BN$14,0.05))))))) | CX36: =CW36*CM36 | CZ36: =IF(CP36<=BR$4,BQ$4,IF(CP36<=BR$5,BQ$5,IF(CP36<=BR$6,BQ$6,IF(CP36<=BR$7,BQ$7,IF(CP36<=BR$12,BQ$12,IF(CP36<=BR$13,BQ$13,IF(CP36<=BR$14,BQ$14,0.05))))))) | DA36: =CZ36*CP36 | DC36: =IF(CS36<=BU$4,BT$4,IF(CS36<=BU$5,BT$5,IF(CS36<=BU$6,BT$6,IF(CS36<=BU$7,BT$7,IF(CS36<=BU$12,BT$12,IF(CS36<=BU$13,BT$13,IF(CS36<=BU$14,BT$14,0.05))))))) | DD36: =DC36*SUM(DA36,CX36,CS36) | DF36: =IF(CV36<=BX$4,BW$4,IF(CV36<=BX$5,BW$5,IF(CV36<=BX$6,BW$6,IF(CV36<=BX$7,BW$7,IF(CV36<=BX$12,BW$12,IF(CV36<=BX$13,BW$13,IF(CV36<=BX$14,BW$14,0.05))))))) | DG36: =DF36*CV36 | DI36: =0.07*SUM(CS36,CX36,DA36,DD36,DG36) | DK36: =SUM(DI36,DG36,DD36,DA36,CX36,CS36) | DL36: =SUM(DG36,DD36,DA36,CX36) | DM36: =DL36/DK36
A37: Cove 2 Options | C37: Liquids | D37: =IF(A37=AS125,AF125,IF(A37=AS126,AF130,IF(A37=AS127,AF135,IF(A37=AS128,AF141,IF(A37=AS129,AF147,IF(A37=AS130,AF152,IF(A37=AS131,AP125,IF(A37=AS132,AP130,IF(A37=AS133,AP135,IF(A37=AS134,AP141,IF(A37=AS135,AP147,IF(A37=AS136,AP152,0)))))))))))) | E37: 0 | F37: LF -- System 2 | AW37: 26000 | AZ37: =AW37 | BC37: =AW37+AZ37 | BF37: =BC37 | BG37: =IF(AW37<=#REF!,#REF!,IF(AW37<=#REF!,#REF!,IF(AW37<=#REF!,#REF!,IF(AW37<=#REF!,#REF!,IF(AW37<=#REF!,#REF!,IF(AW37<=#REF!,#REF!,IF(AW37<=#REF!,#REF!,0.05))))))) | BH37: =BG37*AW37 | BJ37: =IF(AZ37<=#REF!,#REF!,IF(AZ37<=#REF!,#REF!,IF(AZ37<=#REF!,#REF!,IF(AZ37<=#REF!,#REF!,IF(AZ37<=#REF!,#REF!,IF(AZ37<=#REF!,#REF!,IF(AZ37<=#REF!,#REF!,0.05))))))) | BK37: =BJ37*AZ37 | BM37: =IF(BC37<=#REF!,#REF!,IF(BC37<=#REF!,#REF!,IF(BC37<=#REF!,#REF!,IF(BC37<=#REF!,#REF!,IF(BC37<=#REF!,#REF!,IF(BC37<=#REF!,#REF!,IF(BC37<=#REF!,#REF!,0.05))))))) | BN37: =BM37*SUM(BK37,BH37,BC37) | BP37: =IF(BF37<=#REF!,#REF!,IF(BF37<=#REF!,#REF!,IF(BF37<=#REF!,#REF!,IF(BF37<=#REF!,#REF!,IF(BF37<=#REF!,#REF!,IF(BF37<=#REF!,#REF!,IF(BF37<=#REF!,#REF!,0.05))))))) | BQ37: =BP37*BF37 | BS37: =0.07*SUM(BC37,BH37,BK37,BN37,BQ37) | BU37: =SUM(BS37,BQ37,BN37,BK37,BH37,BC37) | BV37: =SUM(BQ37,BN37,BK37,BH37) | BW37: =BV37/BU37 | CM37: 26000 | CP37: =CM37 | CS37: =CM37+CP37 | CV37: =CS37 | CW37: =IF(CM37<=BO$4,BN$4,IF(CM37<=BO$5,BN$5,IF(CM37<=BO$6,BN$6,IF(CM37<=BO$7,BN$7,IF(CM37<=BO$12,BN$12,IF(CM37<=BO$13,BN$13,IF(CM37<=BO$14,BN$14,0.05))))))) | CX37: =CW37*CM37 | CZ37: =IF(CP37<=BR$4,BQ$4,IF(CP37<=BR$5,BQ$5,IF(CP37<=BR$6,BQ$6,IF(CP37<=BR$7,BQ$7,IF(CP37<=BR$12,BQ$12,IF(CP37<=BR$13,BQ$13,IF(CP37<=BR$14,BQ$14,0.05))))))) | DA37: =CZ37*CP37 | DC37: =IF(CS37<=BU$4,BT$4,IF(CS37<=BU$5,BT$5,IF(CS37<=BU$6,BT$6,IF(CS37<=BU$7,BT$7,IF(CS37<=BU$12,BT$12,IF(CS37<=BU$13,BT$13,IF(CS37<=BU$14,BT$14,0.05))))))) | DD37: =DC37*SUM(DA37,CX37,CS37) | DF37: =IF(CV37<=BX$4,BW$4,IF(CV37<=BX$5,BW$5,IF(CV37<=BX$6,BW$6,IF(CV37<=BX$7,BW$7,IF(CV37<=BX$12,BW$12,IF(CV37<=BX$13,BW$13,IF(CV37<=BX$14,BW$14,0.05))))))) | DG37: =DF37*CV37 | DI37: =0.07*SUM(CS37,CX37,DA37,DD37,DG37) | DK37: =SUM(DI37,DG37,DD37,DA37,CX37,CS37) | DL37: =SUM(DG37,DD37,DA37,CX37) | DM37: =DL37/DK37
