Workbook
Name allow: [1]Pricing!$T$86
Name carpet: [1]Pricing!$T$604
Name caulking: [1]Pricing!$T$477
Name ccont: [2]Cover!$K$21
Name conveying: [1]Pricing!$T$769
Name COSTOFWORK: [3]Summary!$D$57
Name dcont: [2]Cover!$K$20
Name demo: [1]Pricing!$T$113
Name drywall: [1]Pricing!$T$581
Name elec: [1]Pricing!$T$861
Name equipment: [1]Pricing!$T$713
Name fee: [1]Cover!$F$25
Name finalclean: [1]Pricing!$T$68
Name fireprotect: [1]Pricing!$T$787
Name flatwork: [1]Pricing!$T$288
Name foundations: [1]Pricing!$T$268
Name furnishings: [1]Pricing!$T$731
Name glass: [1]Pricing!$T$531
Name hmdoorshdw: [1]Pricing!$T$506
Name hvac: [1]Pricing!$T$836
Name landscape: [1]Pricing!$T$242
Name masonry: [1]Pricing!$T$350
Name millwork: [1]Pricing!$T$416
Name PAGE2: #REF!
Name paint: [1]Pricing!$T$667
Name pctiltup: [1]Pricing!$T$325
Name permits: [1]Pricing!$T$40
Name piers: [1]Pricing!$T$223
Name plumb: [1]Pricing!$T$812
Name rcarp: [1]Pricing!$T$392
Name rebar: [1]Pricing!$T$307
Name roofing: [1]Pricing!$T$438
Name sheetmetal: [1]Pricing!$T$459
Name siteconc: [1]Pricing!$T$182
Name siteimprovements: [1]Pricing!$T$205
Name sitework: [1]Pricing!$T$139
Name specconst: [1]Pricing!$T$749
Name specialdoors: [1]Pricing!$T$549
Name specialties: [1]Pricing!$T$695
Name steel: [1]Pricing!$T$370
Name tgasqft: '[3]Building Area'!$H$47
Name tile: [1]Pricing!$T$622
Name units: '[3]Building Area'!$I$42
Name utilities: [1]Pricing!$T$163
Name MarketList: 'Lists'!$A$4:$A$22
Name FloorList: 'Lists'!$B$4:$B$14
Name StateList: 'Lists'!$C$4:$C$10
Name TermsList: 'Lists'!$D$4:$D$6
Name LeadSourceList: 'Lists'!$E$4:$E$12
Name YNList: 'Lists'!$F$4:$F$5

Sheet Info Sheet
A3: Reference #:
B4: New Project Info Sheet | H4: Foundation Tabs
H5: General
B6: Estimating / Sales Action Items | H6: A/R
C7: 1. Add to Project Status Sheet (*by xx). | H7: Payroll
D8: a. Note Contract Status | H8: Division
D9: b. Highlight Deposit Cell if Applicable | H9: UDF
D10: c. Highlight Tax Exempt Cell if Applicable
C11: 2. Request Accounts Payable Contact + (Deposit and Pre-Qual if Required)
C12: 3. Notify Project Coordinator/Sales Admin, if this is a CCIP or OCIP Project
A13: Estimator / Sales Rep: | C13: [Folders: Vanilla = Epoxy -- Blue = Polish/Sealed -- Yellow = Prevailing Wage -- Red = Gyp.]
A14: Project # (Job Number): | E14: Put "!" for Tax Exempt & "$" for Remodel Tax.
A15: Project Name (Description): | E15: "#" for Multi-Scope | G15: MUST INCLUDE ON JOB FOLDER NAME!
A16: Market (Project Class):
A17: Primary Floor:
A18: Division | B18: =IF(ISNUMBER(SEARCH("polish",B17)),"Polish - Commercial",IF(ISNUMBER(SEARCH("epoxy",B17)),"Epoxy - Commercial",IF(ISNUMBER(SEARCH("underlayment",B17)),"Underlayment","")))
A19: State (Geographic Area):
A20: Job Address:
A21: City: | C21: Zip: | E21: State: | F21: =B19
A23: GC / Company/Customer Name: | E23: Estimator:
A24: Address: | E24: Phone:
A25: City, St, Zip: | E25: Email:
A26: Phone:
A27: Reference #:
E28: Other:
A29: Contact (PM):
A30: Phone:
A31: Email:
E32: PA DEADLINE:
A33: Superintendent: | E33: Bill Platform/PayApp: | F33: Treadwell Pay App
A34: Phone: | E34: AP:
A35: Email: | E35: Phone:
E36: Email:
A37: Status of Contract: | E37: *Sales / Estimating - Send intro email asking for contact & connecting Accounting
E38: *Accounting - If no contact listed when billing, call customer
A39: Manufacturer:
A40: System(s):
A41: Color / Blend:
A42: Square Feet [Floor]: | C42: sf | E42: lf
A43: ** Special Transition Detail?
...

Sheet SOV
A1: A | B1: B | C1: C | D1: D | E1: E | F1: F | G1: G | H1: H | I1: I | J1: J | K1: K | L1: L
A2: ITEM | B2: DESCRIPTION OF WORK | C2: SCHEDULED | D2: CHANGES | E2: TOTAL | F2: WORK COMPLETED | H2: MATERIALS | I2: TOTAL | J2: % | K2: BALANCE | L2: RETAINAGE
A3: NO. | C3: VALUE | E3: SCHEDULED | F3: FROM PREVIOUS | G3: THIS PERIOD | H3: PRESENTLY | I3: COMPLETED | J3: COMPLETE | K3: TO FINISH
E4: VALUE | F4: APPLICATION | H4: STORED | I4: AND STORED
I5: TO DATE
A7: 01 | B7: Submittals / Samples | E7: =C7+D7 | F7: 0 | G7: 0 | I7: 0 | J7: 0 | K7: 0 | L7: 0
A8: 02 | B8: Insurance | E8: =C8+D8 | F8: 0 | G8: 0 | I8: 0 | J8: 0 | K8: 0 | L8: 0
A9: 03 | B9: Mobilization | E9: =C9+D9 | F9: 0 | G9: 0 | I9: 0 | J9: 0 | K9: 0 | L9: 0
A10: 04 | B10: Bond (if applicable) | E10: =C10+D10 | F10: 0 | G10: 0 | I10: 0 | J10: 0 | K10: 0 | L10: 0
A11: 05 | B11: Mock Up (if applicable) | E11: =C11+D11 | F11: 0 | G11: 0 | I11: 0 | J11: 0 | K11: 0 | L11: 0
E12: =C12+D12 | F12: 0 | G12: 0 | I12: 0 | J12: 0 | K12: 0 | L12: 0
E13: =C13+D13 | F13: 0 | G13: 0 | I13: 0 | J13: 0 | K13: 0 | L13: 0
E14: =C14+D14 | F14: 0 | G14: 0 | I14: 0 | J14: 0 | K14: 0 | L14: 0
E15: =C15+D15 | F15: 0 | G15: 0 | I15: 0 | J15: 0 | K15: 0 | L15: 0
E16: =C16+D16 | F16: 0 | G16: 0 | I16: 0 | J16: 0 | K16: 0 | L16: 0
E17: =C17+D17 | F17: 0 | G17: 0 | I17: 0 | J17: 0 | K17: 0 | L17: 0
E18: =C18+D18 | F18: 0 | G18: 0 | I18: 0 | J18: 0 | K18: 0 | L18: 0
E19: =C19+D19 | F19: 0 | G19: 0 | I19: 0 | J19: 0 | K19: 0 | L19: 0
E20: =C20+D20 | F20: 0 | G20: 0 | I20: 0 | J20: 0 | K20: 0 | L20: 0
E21: =C21+D21 | F21: 0 | G21: 0 | I21: 0 | J21: 0 | K21: 0 | L21: 0
E22: =C22+D22 | F22: 0 | G22: 0 | I22: 0 | J22: 0 | K22: 0 | L22: 0
E23: =C23+D23 | F23: 0 | G23: 0 | I23: 0 | J23: 0 | K23: 0 | L23: 0
... E33: =C33+D33 | F33: 0 | G33: 0 | I33: 0 | J33: 0 | K33: 0 | L33: 0
E34: 0 | F34: 0 | G34: 0 | I34: 0 | J34: 0 | K34: 0 | L34: 0
E35: 0 | F35: 0 | G35: 0 | I35: 0 | J35: 0 | K35: 0 | L35: 0
E36: 0 | F36: 0 | G36: 0 | I36: 0 | J36: 0 | K36: 0 | L36: 0
E37: 0 | F37: 0 | G37: 0 | I37: 0 | J37: 0 | K37: 0 | L37: 0
E38: 0 | F38: 0 | G38: 0 | I38: 0 | J38: 0 | K38: 0 | L38: 0
E39: 0 | F39: 0 | G39: 0 | I39: 0 | J39: 0 | K39: 0 | L39: 0
E40: 0 | F40: 0 | G40: 0 | I40: 0 | J40: 0 | K40: 0 | L40: 0
E41: 0 | F41: 0 | G41: 0 | I41: 0 | J41: 0 | K41: 0 | L41: 0
E42: 0 | F42: 0 | G42: 0 | I42: 0 | J42: 0 | K42: 0 | L42: 0
E43: 0 | F43: 0 | G43: 0 | I43: 0 | J43: 0 | K43: 0 | L43: 0
B45: Grand Total | C45: =SUM(C7:C44) | D45: =SUM(D7:D44) | E45: =SUM(E7:E44) | F45: =SUM(F7:F44) | G45: =SUM(G7:G44) | H45: =SUM(H7:H44) | I45: =SUM(I7:I44) | J45: =SUM(J7:J44) | ... L45: =SUM(L7:L44)

Sheet Foundation Import
A1: ='Info Sheet'!B14 | B1: ='Info Sheet'!B15 | C1: Misc | D1: ='Info Sheet'!D21 | E1: ='Info Sheet'!B57 | F1: ='Info Sheet'!B66 | G1: ='Info Sheet'!B19 | H1: ='Info Sheet'!B21 | I1: ='Info Sheet'!D21 | J1: ='Info Sheet'!F21
A3: Job Number | B3: Description | C3: Customer Number | D3: Geographical Area | E3: Original Contract | F3: A/P Tax Exempt | G3: Address Line 1 | H3: City | I3: State | J3: Zip

Sheet Invoice
B2: Invoice
B4: Treadwell
B5: 1707 East 123rd Terrace
B6: Olathe Kansas, 66061
B7: accounting@wetreadwell.com
B9: Invoice # | C9: 26.000-01 | F9: ='Info Sheet'!B23 | L9: DOUBLE CHECK CUSTOMER NAME/ADDRESS, PAY TERMS, INVOICE #, PROJECT NO/NAME AND INVOICE/DUE DATE
B10: Date: | F10: ='Info Sheet'!B24
B11: Terms: | C11: ='Info Sheet'!B60 | F11: ='Info Sheet'!B25
B12: Due Date: | C12: =IF(C11="Net 10",C10+10,IF(C11="PO (Net 30)",C10+30,""))
B13: Project/PO No.: | C13: ='Info Sheet'!B14
B14: Project: | C14: ='Info Sheet'!B15
B16: Memo
B17: Payment due 30/10 days from invoice date | L17: CHANGE NET TERMS
B18: We accept ACH payments and paper checks. If paying by check, make it payable to Treadwell. Overdue payments subject to 1.5% monthly interest. Contact Accounting@WeTreadwell.com or 913.396.6216.
B20: SI No. | C20: Description | G20: Amount
B21: 1 | C21: =SOV!B7 | G21: =SOV!E7
B22: 2 | C22: =SOV!B8 | G22: =SOV!E8
B23: 3 | C23: =SOV!B9 | G23: =SOV!E9
B24: 4 | C24: =SOV!B10 | G24: =SOV!E10
B25: 5 | C25: =SOV!B11 | G25: =SOV!E11
B26: 6 | C26: =SOV!B12 | G26: =SOV!E12
B27: 7 | C27: =SOV!B13 | G27: =SOV!E13
B28: 8 | C28: =SOV!B14 | G28: =SOV!E14
B29: 9 | C29: =SOV!B15 | G29: =SOV!E15
B30: 10 | C30: =SOV!B16 | G30: =SOV!E16
B31: Sub-Total: | G31: =SUM(G21:G30)
B33: Total Amount: | G33: =G31
B35: Thank you for your business!

Sheet Deposit
B2: Invoice
B4: Treadwell
B5: 1707 East 123rd Terrace
B6: Olathe Kansas, 66061
B7: accounting@wetreadwell.com
B9: Invoice # | C9: 26.000-01 | F9: ='Info Sheet'!B23 | L9: DOUBLE CHECK CUSTOMER NAME/ADDRESS, PAY TERMS, INVOICE #, PROJECT NO/NAME AND INVOICE/DUE DATE
B10: Date: | F10: ='Info Sheet'!B24
B11: Terms: | C11: ='Info Sheet'!B60 | F11: ='Info Sheet'!B25
B12: Due Date: | C12: =IF(C11="Net 10",C10+10,IF(C11="PO (Net 30)",C10+30,""))
B13: Project/PO No.: | C13: ='Info Sheet'!B14
B14: Project: | C14: ='Info Sheet'!B15
B16: Memo
B17: Payment due 30/10 days from invoice date | L17: CHANGE NET TERMS
B18: We accept ACH payments and paper checks. If paying by check, make it payable to Treadwell. Overdue payments subject to 1.5% monthly interest. Contact Accounting@WeTreadwell.com or 913.396.6216.
B20: SI No. | C20: Description | G20: Amount
B21: 1 | C21: Deposit (25% of contract Amount) | G21: ='Info Sheet'!B57*0.25
B22: 2
B23: 3
B24: Sub-Total: | G24: =SUM(G21:G23)
B26: Total Amount: | G26: =G24
B28: Thank you for your business!

Sheet Lists
A1: Dropdown sources — copied from the master's 'Packet' tab.
A2: Do not edit here; edit the master and re-run prepare_info_sheet_template.py.
A4: -Select- | B4: -Select- | C4: KS - Kansas | D4: Net 10 | E4: Repeat Customer | F4: N
A5: Animal Care | B5: Gypsum Cement Underlayment | C5: MO - Missouri | D5: AIA (GC) | E5: Online | F5: Y
A6: Automotive | B6: Self Leveling Underlayment | C6: OK - Oklahoma | D6: PO (Net 30) | E6: Referral - Partner
A7: Aviation | B7: Topping | C7: NE - Nebraska | E7: Referral - Past Customer
A8: Correctional | B8: Polish - Cream | C8: IA - Iowa | E8: Referral - Supplier
A9: Education | B9: Polish - S&P | C9: AR - Arkansas | E9: Referral - Other
A10: Food & Bev Manufacturing | B10: Polish - Large Aggregate | C10: IL - Illinois | E10: Sapper
A11: Government | B11: Epoxy - Flake | E11: Prospecting / Biz Dev
A12: Healthcare | B12: Epoxy - Quartz | E12: Other
A13: Industial & Manufacturing | B13: Epoxy - Urethane Cement
A14: Labs | B14: Other
A15: Multifamily & Sr. Living
A16: Office Space
A17: Pharmaceuticals
A18: Recreation & Entertainment
A19: Religious
A20: Restaurant
A21: Retail
A22: Technology
